Workbook

Sheet Home

Sheet INPUT DATA
A1: Input Data Sheet for Electronic-Class Record (ECR) for Class Adviser
B7: SCHOOL INFORMATION | J7: LEARNERS' DATA
C10: REGION | E10: : | F10: NCR | K10: MALE | M10: LRN | N10: BIRTHDATE | P10: FEMALE | R10: LRN | S10: BIRTHDATE
C11: DIVISION | E11: : | F11: LAS PINAS | K11: 1 | L11: A | M11: 123456789012 | N11: 40355 | P11: 1
C12: CITY/MUNICIPALITY | E12: : | F12: LAS PINAS CITY | K12: 2 | L12: B | M12: 2 | N12: 40574 | P12: 2
C13: DISTRICT | E13: : | F13: DISTRICT II | K13: 3 | P13: 3
K14: 4 | P14: 4
C15: SCHOOL ID | E15: : | F15: 305434 | K15: 5 | P15: 5
C16: SCHOOL NAME | E16: : | F16: LAS PINAS EAST NATIONAL HIGH SCHOOL | K16: 6 | P16: 6
K17: 7 | P17: 7
C18: SCHOOL YEAR | E18: : | F18: 2026-2027 | K18: 8 | P18: 8
C19: SCHOOL HEAD | E19: : | F19: NELSON A. IMACULATA JR. | K19: 9 | P19: 9
K20: 10 | P20: 10
K21: 11 | P21: 11
K22: 12 | P22: 12
B23: TEACHER, GRADE LEVEL, SECTION INFORMATION | K23: 13 | P23: 13
K24: 14 | P24: 14
K25: 15 | P25: 15
C26: ADVISER | E26: : | F26: ROSALINDA S. VALE | K26: 16 | P26: 16
C27: GRADE LEVEL | E27: : | F27: 10 | G27: (Accepts Grades 4 to 10 only) | K27: 17 | P27: 17
C28: SECTION | E28: : | F28: PAMAYPAY | K28: 18 | P28: 18
K29: 19 | P29: 19
C30: IMPORTANT NOTE: This is the official and final version of the file. All tabs are password-protected to prevent accidental formula edits and maintain the accuracy and integrity of the data. If you identify any inconsistencies or issues, particularly with the formulas, please report them for appropriate review and necessary correction. | K30: 20 | P30: 20
K31: 21 | P31: 21
K32: 22 | P32: 22
K33: 23 | P33: 23
K34: 24 | P34: 24
K35: 25 | P35: 25
K36: 26 | P36: 26
K37: 27 | P37: 27
K38: 28 | P38: 28
K39: 29 | P39: 29
K40: 30 | P40: 30
K41: 31 | P41: 31
K42: 32 | P42: 32
... K60: 50 | P60: 50
T62: 2026_v1.0

Sheet TERM 1 SUMMARY
A1: CLASS SUMMARY - TERM 1
D5: REGION | E5: ='INPUT DATA'!F10 -> NCR | I5: DIVISION | K5: ='INPUT DATA'!F11 -> LAS PINAS
D6: SCHOOL NAME | E6: ='INPUT DATA'!F16 -> LAS PINAS EAST NATIONAL HIGH SCHOOL | I6: SCHOOL ID | K6: ='INPUT DATA'!F15 -> 305434 | S6: SCHOOL YEAR | T6: ='INPUT DATA'!F18 -> 2026-2027
B9: FIRST TERM | F9: GRADE LEVEL | G9: ='INPUT DATA'!F27 -> 10 | L9: ADVISER | N9: ='INPUT DATA'!F26 -> ROSALINDA S. VALE
F10: SECTION | G10: ='INPUT DATA'!F28 -> PAMAYPAY
B11: LEARNERS' NAMES | F11: LRN | H11: Date of Birth | I11: Age | J11: Sex | K11: Learning Areas | T11: Final Grade | U11: Rank
K12: Filipino | L12: English | M12: Mathematics | N12: Science | O12: AP | P12: GMRC/VE | Q12: EPP/TLE | R12: MAPEH
R13: M A | S13: P E H
B15: 1 | C15: =IF('INPUT DATA'!L11="","",'INPUT DATA'!L11) -> A | F15: =IF('INPUT DATA'!M11="","",'INPUT DATA'!M11) -> 123456789012 | H15: =IF('INPUT DATA'!N11="","",'INPUT DATA'!N11) -> 40355 | I15: =IF(H15="","",DATEDIF(H15,TODAY(),"Y")) -> 16 | J15: M | T15: =IF(COUNT(K15:S15)=0,"",ROUND((K15+L15+M15+N15+O15+S15)/6,0)) | U15: =IF(T15="","",_xlfn.RANK.AVG(T15,$T$15:$T$115))
B16: 2 | C16: =IF('INPUT DATA'!L12="","",'INPUT DATA'!L12) -> B | F16: =IF('INPUT DATA'!M12="","",'INPUT DATA'!M12) -> 2 | H16: =IF('INPUT DATA'!N12="","",'INPUT DATA'!N12) -> 40574 | I16: =IF(H16="","",DATEDIF(H16,TODAY(),"Y")) -> 15 | T16: =IF(COUNT(K16:S16)=0,"",ROUND((K16+L16+M16+N16+O16+S16)/6,0)) | U16: =IF(T16="","",_xlfn.RANK.AVG(T16,$T$15:$T$115))
B17: 3 | C17: =IF('INPUT DATA'!L13="","",'INPUT DATA'!L13) | F17: =IF('INPUT DATA'!M13="","",'INPUT DATA'!M13) | H17: =IF('INPUT DATA'!N13="","",'INPUT DATA'!N13) | I17: =IF(H17="","",DATEDIF(H17,TODAY(),"Y")) | T17: =IF(COUNT(K17:S17)=0,"",ROUND((K17+L17+M17+N17+O17+S17)/6,0)) | U17: =IF(T17="","",_xlfn.RANK.AVG(T17,$T$15:$T$115))
B18: 4 | C18: =IF('INPUT DATA'!L14="","",'INPUT DATA'!L14) | F18: =IF('INPUT DATA'!M14="","",'INPUT DATA'!M14) | H18: =IF('INPUT DATA'!N14="","",'INPUT DATA'!N14) | I18: =IF(H18="","",DATEDIF(H18,TODAY(),"Y")) | T18: =IF(COUNT(K18:S18)=0,"",ROUND((K18+L18+M18+N18+O18+S18)/6,0)) | U18: =IF(T18="","",_xlfn.RANK.AVG(T18,$T$15:$T$115))
B19: 5 | C19: =IF('INPUT DATA'!L15="","",'INPUT DATA'!L15) | F19: =IF('INPUT DATA'!M15="","",'INPUT DATA'!M15) | H19: =IF('INPUT DATA'!N15="","",'INPUT DATA'!N15) | I19: =IF(H19="","",DATEDIF(H19,TODAY(),"Y")) | T19: =IF(COUNT(K19:S19)=0,"",ROUND((K19+L19+M19+N19+O19+S19)/6,0)) | U19: =IF(T19="","",_xlfn.RANK.AVG(T19,$T$15:$T$115))
B20: 6 | C20: =IF('INPUT DATA'!L16="","",'INPUT DATA'!L16) | F20: =IF('INPUT DATA'!M16="","",'INPUT DATA'!M16) | H20: =IF('INPUT DATA'!N16="","",'INPUT DATA'!N16) | I20: =IF(H20="","",DATEDIF(H20,TODAY(),"Y")) | T20: =IF(COUNT(K20:S20)=0,"",ROUND((K20+L20+M20+N20+O20+S20)/6,0)) | U20: =IF(T20="","",_xlfn.RANK.AVG(T20,$T$15:$T$115))
B21: 7 | C21: =IF('INPUT DATA'!L17="","",'INPUT DATA'!L17) | F21: =IF('INPUT DATA'!M17="","",'INPUT DATA'!M17) | H21: =IF('INPUT DATA'!N17="","",'INPUT DATA'!N17) | I21: =IF(H21="","",DATEDIF(H21,TODAY(),"Y")) | T21: =IF(COUNT(K21:S21)=0,"",ROUND((K21+L21+M21+N21+O21+S21)/6,0)) | U21: =IF(T21="","",_xlfn.RANK.AVG(T21,$T$15:$T$115))
B22: 8 | C22: =IF('INPUT DATA'!L18="","",'INPUT DATA'!L18) | F22: =IF('INPUT DATA'!M18="","",'INPUT DATA'!M18) | H22: =IF('INPUT DATA'!N18="","",'INPUT DATA'!N18) | I22: =IF(H22="","",DATEDIF(H22,TODAY(),"Y")) | T22: =IF(COUNT(K22:S22)=0,"",ROUND((K22+L22+M22+N22+O22+S22)/6,0)) | U22: =IF(T22="","",_xlfn.RANK.AVG(T22,$T$15:$T$115))
B23: 9 | C23: =IF('INPUT DATA'!L19="","",'INPUT DATA'!L19) | F23: =IF('INPUT DATA'!M19="","",'INPUT DATA'!M19) | H23: =IF('INPUT DATA'!N19="","",'INPUT DATA'!N19) | I23: =IF(H23="","",DATEDIF(H23,TODAY(),"Y")) | T23: =IF(COUNT(K23:S23)=0,"",ROUND((K23+L23+M23+N23+O23+S23)/6,0)) | U23: =IF(T23="","",_xlfn.RANK.AVG(T23,$T$15:$T$115))
B24: 10 | C24: =IF('INPUT DATA'!L20="","",'INPUT DATA'!L20) | F24: =IF('INPUT DATA'!M20="","",'INPUT DATA'!M20) | H24: =IF('INPUT DATA'!N20="","",'INPUT DATA'!N20) | I24: =IF(H24="","",DATEDIF(H24,TODAY(),"Y")) | T24: =IF(COUNT(K24:S24)=0,"",ROUND((K24+L24+M24+N24+O24+S24)/6,0)) | U24: =IF(T24="","",_xlfn.RANK.AVG(T24,$T$15:$T$115))
B25: 11 | C25: =IF('INPUT DATA'!L21="","",'INPUT DATA'!L21) | F25: =IF('INPUT DATA'!M21="","",'INPUT DATA'!M21) | H25: =IF('INPUT DATA'!N21="","",'INPUT DATA'!N21) | I25: =IF(H25="","",DATEDIF(H25,TODAY(),"Y")) | T25: =IF(COUNT(K25:S25)=0,"",ROUND((K25+L25+M25+N25+O25+S25)/6,0)) | U25: =IF(T25="","",_xlfn.RANK.AVG(T25,$T$15:$T$115))
B26: 12 | C26: =IF('INPUT DATA'!L22="","",'INPUT DATA'!L22) | F26: =IF('INPUT DATA'!M22="","",'INPUT DATA'!M22) | H26: =IF('INPUT DATA'!N22="","",'INPUT DATA'!N22) | I26: =IF(H26="","",DATEDIF(H26,TODAY(),"Y")) | T26: =IF(COUNT(K26:S26)=0,"",ROUND((K26+L26+M26+N26+O26+S26)/6,0)) | U26: =IF(T26="","",_xlfn.RANK.AVG(T26,$T$15:$T$115))
B27: 13 | C27: =IF('INPUT DATA'!L23="","",'INPUT DATA'!L23) | F27: =IF('INPUT DATA'!M23="","",'INPUT DATA'!M23) | H27: =IF('INPUT DATA'!N23="","",'INPUT DATA'!N23) | I27: =IF(H27="","",DATEDIF(H27,TODAY(),"Y")) | T27: =IF(COUNT(K27:S27)=0,"",ROUND((K27+L27+M27+N27+O27+S27)/6,0)) | U27: =IF(T27="","",_xlfn.RANK.AVG(T27,$T$15:$T$115))
... B64: 50 | C64: =IF('INPUT DATA'!L60="","",'INPUT DATA'!L60) | F64: =IF('INPUT DATA'!M60="","",'INPUT DATA'!M60) | H64: =IF('INPUT DATA'!N60="","",'INPUT DATA'!N60) | I64: =IF(H64="","",DATEDIF(H64,TODAY(),"Y")) | T64: =IF(COUNT(K64:S64)=0,"",ROUND((K64+L64+M64+N64+O64+S64)/6,0)) | U64: =IF(T64="","",_xlfn.RANK.AVG(T64,$T$15:$T$115))
B65: FEMALE
B66: 1 | C66: =IF('INPUT DATA'!Q11="","",'INPUT DATA'!Q11) | F66: =IF('INPUT DATA'!T11="","",'INPUT DATA'!T11) | H66: =IF('INPUT DATA'!S11="","",'INPUT DATA'!S11) | I66: =IF(H66="","",DATEDIF(H66,TODAY(),"Y")) | T66: =IF(COUNT(K66:S66)=0,"",ROUND((K66+L66+M66+N66+O66+S66)/6,0)) | U66: =IF(T66="","",_xlfn.RANK.AVG(T66,$T$15:$T$115))
B67: 2 | C67: =IF('INPUT DATA'!Q12="","",'INPUT DATA'!Q12) | F67: =IF('INPUT DATA'!T12="","",'INPUT DATA'!T12) | H67: =IF('INPUT DATA'!S12="","",'INPUT DATA'!S12) | I67: =IF(H67="","",DATEDIF(H67,TODAY(),"Y")) | T67: =IF(COUNT(K67:S67)=0,"",ROUND((K67+L67+M67+N67+O67+S67)/6,0)) | U67: =IF(T67="","",_xlfn.RANK.AVG(T67,$T$15:$T$115))
B68: 3 | C68: =IF('INPUT DATA'!Q13="","",'INPUT DATA'!Q13) | F68: =IF('INPUT DATA'!T13="","",'INPUT DATA'!T13) | H68: =IF('INPUT DATA'!S13="","",'INPUT DATA'!S13) | I68: =IF(H68="","",DATEDIF(H68,TODAY(),"Y")) | T68: =IF(COUNT(K68:S68)=0,"",ROUND((K68+L68+M68+N68+O68+S68)/6,0)) | U68: =IF(T68="","",_xlfn.RANK.AVG(T68,$T$15:$T$115))
B69: 4 | C69: =IF('INPUT DATA'!Q14="","",'INPUT DATA'!Q14) | F69: =IF('INPUT DATA'!T14="","",'INPUT DATA'!T14) | H69: =IF('INPUT DATA'!S14="","",'INPUT DATA'!S14) | I69: =IF(H69="","",DATEDIF(H69,TODAY(),"Y")) | T69: =IF(COUNT(K69:S69)=0,"",ROUND((K69+L69+M69+N69+O69+S69)/6,0)) | U69: =IF(T69="","",_xlfn.RANK.AVG(T69,$T$15:$T$115))
B70: 5 | C70: =IF('INPUT DATA'!Q15="","",'INPUT DATA'!Q15) | F70: =IF('INPUT DATA'!T15="","",'INPUT DATA'!T15) | H70: =IF('INPUT DATA'!S15="","",'INPUT DATA'!S15) | I70: =IF(H70="","",DATEDIF(H70,TODAY(),"Y")) | T70: =IF(COUNT(K70:S70)=0,"",ROUND((K70+L70+M70+N70+O70+S70)/6,0)) | U70: =IF(T70="","",_xlfn.RANK.AVG(T70,$T$15:$T$115))
B71: 6 | C71: =IF('INPUT DATA'!Q16="","",'INPUT DATA'!Q16) | F71: =IF('INPUT DATA'!T16="","",'INPUT DATA'!T16) | H71: =IF('INPUT DATA'!S16="","",'INPUT DATA'!S16) | I71: =IF(H71="","",DATEDIF(H71,TODAY(),"Y")) | T71: =IF(COUNT(K71:S71)=0,"",ROUND((K71+L71+M71+N71+O71+S71)/6,0)) | U71: =IF(T71="","",_xlfn.RANK.AVG(T71,$T$15:$T$115))
B72: 7 | C72: =IF('INPUT DATA'!Q17="","",'INPUT DATA'!Q17) | F72: =IF('INPUT DATA'!T17="","",'INPUT DATA'!T17) | H72: =IF('INPUT DATA'!S17="","",'INPUT DATA'!S17) | I72: =IF(H72="","",DATEDIF(H72,TODAY(),"Y")) | T72: =IF(COUNT(K72:S72)=0,"",ROUND((K72+L72+M72+N72+O72+S72)/6,0)) | U72: =IF(T72="","",_xlfn.RANK.AVG(T72,$T$15:$T$115))
B73: 8 | C73: =IF('INPUT DATA'!Q18="","",'INPUT DATA'!Q18) | F73: =IF('INPUT DATA'!T18="","",'INPUT DATA'!T18) | H73: =IF('INPUT DATA'!S18="","",'INPUT DATA'!S18) | I73: =IF(H73="","",DATEDIF(H73,TODAY(),"Y")) | T73: =IF(COUNT(K73:S73)=0,"",ROUND((K73+L73+M73+N73+O73+S73)/6,0)) | U73: =IF(T73="","",_xlfn.RANK.AVG(T73,$T$15:$T$115))
B74: 9 | C74: =IF('INPUT DATA'!Q19="","",'INPUT DATA'!Q19) | F74: =IF('INPUT DATA'!T19="","",'INPUT DATA'!T19) | H74: =IF('INPUT DATA'!S19="","",'INPUT DATA'!S19) | I74: =IF(H74="","",DATEDIF(H74,TODAY(),"Y")) | T74: =IF(COUNT(K74:S74)=0,"",ROUND((K74+L74+M74+N74+O74+S74)/6,0)) | U74: =IF(T74="","",_xlfn.RANK.AVG(T74,$T$15:$T$115))
B75: 10 | C75: =IF('INPUT DATA'!Q20="","",'INPUT DATA'!Q20) | F75: =IF('INPUT DATA'!T20="","",'INPUT DATA'!T20) | H75: =IF('INPUT DATA'!S20="","",'INPUT DATA'!S20) | I75: =IF(H75="","",DATEDIF(H75,TODAY(),"Y")) | T75: =IF(COUNT(K75:S75)=0,"",ROUND((K75+L75+M75+N75+O75+S75)/6,0)) | U75: =IF(T75="","",_xlfn.RANK.AVG(T75,$T$15:$T$115))
B76: 11 | C76: =IF('INPUT DATA'!Q21="","",'INPUT DATA'!Q21) | F76: =IF('INPUT DATA'!T21="","",'INPUT DATA'!T21) | H76: =IF('INPUT DATA'!S21="","",'INPUT DATA'!S21) | I76: =IF(H76="","",DATEDIF(H76,TODAY(),"Y")) | T76: =IF(COUNT(K76:S76)=0,"",ROUND((K76+L76+M76+N76+O76+S76)/6,0)) | U76: =IF(T76="","",_xlfn.RANK.AVG(T76,$T$15:$T$115))
B77: 12 | C77: =IF('INPUT DATA'!Q22="","",'INPUT DATA'!Q22) | F77: =IF('INPUT DATA'!T22="","",'INPUT DATA'!T22) | H77: =IF('INPUT DATA'!S22="","",'INPUT DATA'!S22) | I77: =IF(H77="","",DATEDIF(H77,TODAY(),"Y")) | T77: =IF(COUNT(K77:S77)=0,"",ROUND((K77+L77+M77+N77+O77+S77)/6,0)) | U77: =IF(T77="","",_xlfn.RANK.AVG(T77,$T$15:$T$115))
... B115: 50 | C115: =IF('INPUT DATA'!Q60="","",'INPUT DATA'!Q60) | F115: =IF('INPUT DATA'!T60="","",'INPUT DATA'!T60) | H115: =IF('INPUT DATA'!S60="","",'INPUT DATA'!S60) | I115: =IF(H115="","",DATEDIF(H115,TODAY(),"Y")) | T115: =IF(COUNT(K115:S115)=0,"",ROUND((K115+L115+M115+N115+O115+S115)/6,0)) | U115: =IF(T115="","",_xlfn.RANK.AVG(T115,$T$15:$T$115))

Sheet TERM 2 SUMMARY
A1: CLASS SUMMARY - TERM 2
D5: REGION | E5: ='INPUT DATA'!F10 -> NCR | I5: DIVISION | K5: ='INPUT DATA'!F11 -> LAS PINAS
D6: SCHOOL NAME | E6: ='INPUT DATA'!F16 -> LAS PINAS EAST NATIONAL HIGH SCHOOL | I6: SCHOOL ID | K6: ='INPUT DATA'!F15 -> 305434 | S6: SCHOOL YEAR | T6: ='INPUT DATA'!F18 -> 2026-2027
B9: SECOND TERM | F9: GRADE LEVEL | G9: ='INPUT DATA'!F27 -> 10 | L9: ADVISER | N9: ='INPUT DATA'!F26 -> ROSALINDA S. VALE
F10: SECTION | G10: ='INPUT DATA'!F28 -> PAMAYPAY
B11: LEARNERS' NAMES | F11: LRN | H11: Date of Birth | I11: Age | J11: Sex | K11: Learning Areas | T11: Final Grade | U11: Rank
K12: Filipino | L12: English | M12: Mathematics | N12: Science | O12: AP | P12: GMRC/VE | Q12: EPP/TLE | R12: MAPEH
R13: M A | S13: P E H
B15: 1 | C15: =IF('INPUT DATA'!L11="","",'INPUT DATA'!L11) -> A | F15: =IF('INPUT DATA'!M11="","",'INPUT DATA'!M11) -> 123456789012 | H15: =IF('INPUT DATA'!N11="","",'INPUT DATA'!N11) -> 40355 | I15: =IF(H15="","",DATEDIF(H15,TODAY(),"Y")) -> 16 | J15: M | K15: 91 | L15: 90 | M15: 92 | N15: 90 | O15: 91 | P15: 92 | Q15: 91 | R15: 92 | S15: 92 | T15: =IF(COUNT(K15:S15)=0,"",ROUND((K15+L15+M15+N15+O15+S15)/6,0)) -> 91 | U15: =IF(T15="","",_xlfn.RANK.AVG(T15,$T$15:$T$115)) -> 2.5
B16: 2 | C16: =IF('INPUT DATA'!L12="","",'INPUT DATA'!L12) -> B | F16: =IF('INPUT DATA'!M12="","",'INPUT DATA'!M12) -> 2 | H16: =IF('INPUT DATA'!N12="","",'INPUT DATA'!N12) -> 40574 | I16: =IF(H16="","",DATEDIF(H16,TODAY(),"Y")) -> 15 | J16: M | K16: 90 | L16: 93 | M16: 89 | N16: 90 | O16: 88 | P16: 90 | Q16: 91 | R16: 90 | S16: 90 | T16: =IF(COUNT(K16:S16)=0,"",ROUND((K16+L16+M16+N16+O16+S16)/6,0)) -> 90 | U16: =IF(T16="","",_xlfn.RANK.AVG(T16,$T$15:$T$115)) -> 5
B17: 3 | C17: =IF('INPUT DATA'!L13="","",'INPUT DATA'!L13) | F17: =IF('INPUT DATA'!M13="","",'INPUT DATA'!M13) | H17: =IF('INPUT DATA'!N13="","",'INPUT DATA'!N13) | I17: =IF(H17="","",DATEDIF(H17,TODAY(),"Y")) | J17: M | K17: 92 | L17: 89 | M17: 87 | N17: 90 | O17: 84 | P17: 86 | Q17: 91 | R17: 86 | S17: 86 | T17: =IF(COUNT(K17:S17)=0,"",ROUND((K17+L17+M17+N17+O17+S17)/6,0)) -> 88 | U17: =IF(T17="","",_xlfn.RANK.AVG(T17,$T$15:$T$115)) -> 6
B18: 4 | C18: =IF('INPUT DATA'!L14="","",'INPUT DATA'!L14) | F18: =IF('INPUT DATA'!M14="","",'INPUT DATA'!M14) | H18: =IF('INPUT DATA'!N14="","",'INPUT DATA'!N14) | I18: =IF(H18="","",DATEDIF(H18,TODAY(),"Y")) | T18: =IF(COUNT(K18:S18)=0,"",ROUND((K18+L18+M18+N18+O18+S18)/6,0)) | U18: =IF(T18="","",_xlfn.RANK.AVG(T18,$T$15:$T$115))
B19: 5 | C19: =IF('INPUT DATA'!L15="","",'INPUT DATA'!L15) | F19: =IF('INPUT DATA'!M15="","",'INPUT DATA'!M15) | H19: =IF('INPUT DATA'!N15="","",'INPUT DATA'!N15) | I19: =IF(H19="","",DATEDIF(H19,TODAY(),"Y")) | T19: =IF(COUNT(K19:S19)=0,"",ROUND((K19+L19+M19+N19+O19+S19)/6,0)) | U19: =IF(T19="","",_xlfn.RANK.AVG(T19,$T$15:$T$115))
B20: 6 | C20: =IF('INPUT DATA'!L16="","",'INPUT DATA'!L16) | F20: =IF('INPUT DATA'!M16="","",'INPUT DATA'!M16) | H20: =IF('INPUT DATA'!N16="","",'INPUT DATA'!N16) | I20: =IF(H20="","",DATEDIF(H20,TODAY(),"Y")) | T20: =IF(COUNT(K20:S20)=0,"",ROUND((K20+L20+M20+N20+O20+S20)/6,0)) | U20: =IF(T20="","",_xlfn.RANK.AVG(T20,$T$15:$T$115))
B21: 7 | C21: =IF('INPUT DATA'!L17="","",'INPUT DATA'!L17) | F21: =IF('INPUT DATA'!M17="","",'INPUT DATA'!M17) | H21: =IF('INPUT DATA'!N17="","",'INPUT DATA'!N17) | I21: =IF(H21="","",DATEDIF(H21,TODAY(),"Y")) | T21: =IF(COUNT(K21:S21)=0,"",ROUND((K21+L21+M21+N21+O21+S21)/6,0)) | U21: =IF(T21="","",_xlfn.RANK.AVG(T21,$T$15:$T$115))
B22: 8 | C22: =IF('INPUT DATA'!L18="","",'INPUT DATA'!L18) | F22: =IF('INPUT DATA'!M18="","",'INPUT DATA'!M18) | H22: =IF('INPUT DATA'!N18="","",'INPUT DATA'!N18) | I22: =IF(H22="","",DATEDIF(H22,TODAY(),"Y")) | T22: =IF(COUNT(K22:S22)=0,"",ROUND((K22+L22+M22+N22+O22+S22)/6,0)) | U22: =IF(T22="","",_xlfn.RANK.AVG(T22,$T$15:$T$115))
B23: 9 | C23: =IF('INPUT DATA'!L19="","",'INPUT DATA'!L19) | F23: =IF('INPUT DATA'!M19="","",'INPUT DATA'!M19) | H23: =IF('INPUT DATA'!N19="","",'INPUT DATA'!N19) | I23: =IF(H23="","",DATEDIF(H23,TODAY(),"Y")) | T23: =IF(COUNT(K23:S23)=0,"",ROUND((K23+L23+M23+N23+O23+S23)/6,0)) | U23: =IF(T23="","",_xlfn.RANK.AVG(T23,$T$15:$T$115))
B24: 10 | C24: =IF('INPUT DATA'!L20="","",'INPUT DATA'!L20) | F24: =IF('INPUT DATA'!M20="","",'INPUT DATA'!M20) | H24: =IF('INPUT DATA'!N20="","",'INPUT DATA'!N20) | I24: =IF(H24="","",DATEDIF(H24,TODAY(),"Y")) | T24: =IF(COUNT(K24:S24)=0,"",ROUND((K24+L24+M24+N24+O24+S24)/6,0)) | U24: =IF(T24="","",_xlfn.RANK.AVG(T24,$T$15:$T$115))
B25: 11 | C25: =IF('INPUT DATA'!L21="","",'INPUT DATA'!L21) | F25: =IF('INPUT DATA'!M21="","",'INPUT DATA'!M21) | H25: =IF('INPUT DATA'!N21="","",'INPUT DATA'!N21) | I25: =IF(H25="","",DATEDIF(H25,TODAY(),"Y")) | T25: =IF(COUNT(K25:S25)=0,"",ROUND((K25+L25+M25+N25+O25+S25)/6,0)) | U25: =IF(T25="","",_xlfn.RANK.AVG(T25,$T$15:$T$115))
B26: 12 | C26: =IF('INPUT DATA'!L22="","",'INPUT DATA'!L22) | F26: =IF('INPUT DATA'!M22="","",'INPUT DATA'!M22) | H26: =IF('INPUT DATA'!N22="","",'INPUT DATA'!N22) | I26: =IF(H26="","",DATEDIF(H26,TODAY(),"Y")) | T26: =IF(COUNT(K26:S26)=0,"",ROUND((K26+L26+M26+N26+O26+S26)/6,0)) | U26: =IF(T26="","",_xlfn.RANK.AVG(T26,$T$15:$T$115))
B27: 13 | C27: =IF('INPUT DATA'!L23="","",'INPUT DATA'!L23) | F27: =IF('INPUT DATA'!M23="","",'INPUT DATA'!M23) | H27: =IF('INPUT DATA'!N23="","",'INPUT DATA'!N23) | I27: =IF(H27="","",DATEDIF(H27,TODAY(),"Y")) | T27: =IF(COUNT(K27:S27)=0,"",ROUND((K27+L27+M27+N27+O27+S27)/6,0)) | U27: =IF(T27="","",_xlfn.RANK.AVG(T27,$T$15:$T$115))
B28: 14 | C28: =IF('INPUT DATA'!L24="","",'INPUT DATA'!L24) | F28: =IF('INPUT DATA'!M24="","",'INPUT DATA'!M24) | H28: =IF('INPUT DATA'!N24="","",'INPUT DATA'!N24) | I28: =IF(H28="","",DATEDIF(H28,TODAY(),"Y")) | T28: =IF(COUNT(K28:S28)=0,"",ROUND((K28+L28+M28+N28+O28+S28)/6,0)) | U28: =IF(T28="","",_xlfn.RANK.AVG(T28,$T$15:$T$115))
B29: 15 | C29: =IF('INPUT DATA'!L25="","",'INPUT DATA'!L25) | F29: =IF('INPUT DATA'!M25="","",'INPUT DATA'!M25) | H29: =IF('INPUT DATA'!N25="","",'INPUT DATA'!N25) | I29: =IF(H29="","",DATEDIF(H29,TODAY(),"Y")) | T29: =IF(COUNT(K29:S29)=0,"",ROUND((K29+L29+M29+N29+O29+S29)/6,0)) | U29: =IF(T29="","",_xlfn.RANK.AVG(T29,$T$15:$T$115))
... B64: 50 | C64: =IF('INPUT DATA'!L60="","",'INPUT DATA'!L60) | F64: =IF('INPUT DATA'!M60="","",'INPUT DATA'!M60) | H64: =IF('INPUT DATA'!N60="","",'INPUT DATA'!N60) | I64: =IF(H64="","",DATEDIF(H64,TODAY(),"Y")) | T64: =IF(COUNT(K64:S64)=0,"",ROUND((K64+L64+M64+N64+O64+S64)/6,0)) | U64: =IF(T64="","",_xlfn.RANK.AVG(T64,$T$15:$T$115))
B65: FEMALE
B66: 1 | C66: =IF('INPUT DATA'!Q11="","",'INPUT DATA'!Q11) | F66: ='INPUT DATA'!R11 | H66: =IF('INPUT DATA'!S11="","",'INPUT DATA'!S11) | I66: =IF(H66="","",DATEDIF(H66,TODAY(),"Y")) | J66: F | K66: 90 | L66: 91 | M66: 89 | N66: 90 | O66: 91 | S66: 92 | T66: =IF(COUNT(K66:S66)=0,"",ROUND((K66+L66+M66+N66+O66+S66)/6,0)) -> 91 | U66: =IF(T66="","",_xlfn.RANK.AVG(T66,$T$15:$T$115)) -> 2.5
B67: 2 | C67: =IF('INPUT DATA'!Q12="","",'INPUT DATA'!Q12) | F67: ='INPUT DATA'!R12 | H67: =IF('INPUT DATA'!S12="","",'INPUT DATA'!S12) | I67: =IF(H67="","",DATEDIF(H67,TODAY(),"Y")) | J67: F | K67: 92 | L67: 93 | M67: 89 | N67: 90 | O67: 90 | S67: 90 | T67: =IF(COUNT(K67:S67)=0,"",ROUND((K67+L67+M67+N67+O67+S67)/6,0)) -> 91 | U67: =IF(T67="","",_xlfn.RANK.AVG(T67,$T$15:$T$115)) -> 2.5
B68: 3 | C68: =IF('INPUT DATA'!Q13="","",'INPUT DATA'!Q13) | F68: ='INPUT DATA'!R13 | H68: =IF('INPUT DATA'!S13="","",'INPUT DATA'!S13) | I68: =IF(H68="","",DATEDIF(H68,TODAY(),"Y")) | J68: F | K68: 91 | L68: 92 | M68: 91 | N68: 90 | O68: 92 | S68: 89 | T68: =IF(COUNT(K68:S68)=0,"",ROUND((K68+L68+M68+N68+O68+S68)/6,0)) -> 91 | U68: =IF(T68="","",_xlfn.RANK.AVG(T68,$T$15:$T$115)) -> 2.5
B69: 4 | C69: =IF('INPUT DATA'!Q14="","",'INPUT DATA'!Q14) | F69: =IF('INPUT DATA'!T14="","",'INPUT DATA'!T14) | H69: =IF('INPUT DATA'!S14="","",'INPUT DATA'!S14) | I69: =IF(H69="","",DATEDIF(H69,TODAY(),"Y")) | T69: =IF(COUNT(K69:S69)=0,"",ROUND((K69+L69+M69+N69+O69+S69)/6,0)) | U69: =IF(T69="","",_xlfn.RANK.AVG(T69,$T$15:$T$115))
B70: 5 | C70: =IF('INPUT DATA'!Q15="","",'INPUT DATA'!Q15) | F70: =IF('INPUT DATA'!T15="","",'INPUT DATA'!T15) | H70: =IF('INPUT DATA'!S15="","",'INPUT DATA'!S15) | I70: =IF(H70="","",DATEDIF(H70,TODAY(),"Y")) | T70: =IF(COUNT(K70:S70)=0,"",ROUND((K70+L70+M70+N70+O70+S70)/6,0)) | U70: =IF(T70="","",_xlfn.RANK.AVG(T70,$T$15:$T$115))
B71: 6 | C71: =IF('INPUT DATA'!Q16="","",'INPUT DATA'!Q16) | F71: =IF('INPUT DATA'!T16="","",'INPUT DATA'!T16) | H71: =IF('INPUT DATA'!S16="","",'INPUT DATA'!S16) | I71: =IF(H71="","",DATEDIF(H71,TODAY(),"Y")) | T71: =IF(COUNT(K71:S71)=0,"",ROUND((K71+L71+M71+N71+O71+S71)/6,0)) | U71: =IF(T71="","",_xlfn.RANK.AVG(T71,$T$15:$T$115))
B72: 7 | C72: =IF('INPUT DATA'!Q17="","",'INPUT DATA'!Q17) | F72: =IF('INPUT DATA'!T17="","",'INPUT DATA'!T17) | H72: =IF('INPUT DATA'!S17="","",'INPUT DATA'!S17) | I72: =IF(H72="","",DATEDIF(H72,TODAY(),"Y")) | T72: =IF(COUNT(K72:S72)=0,"",ROUND((K72+L72+M72+N72+O72+S72)/6,0)) | U72: =IF(T72="","",_xlfn.RANK.AVG(T72,$T$15:$T$115))
B73: 8 | C73: =IF('INPUT DATA'!Q18="","",'INPUT DATA'!Q18) | F73: =IF('INPUT DATA'!T18="","",'INPUT DATA'!T18) | H73: =IF('INPUT DATA'!S18="","",'INPUT DATA'!S18) | I73: =IF(H73="","",DATEDIF(H73,TODAY(),"Y")) | T73: =IF(COUNT(K73:S73)=0,"",ROUND((K73+L73+M73+N73+O73+S73)/6,0)) | U73: =IF(T73="","",_xlfn.RANK.AVG(T73,$T$15:$T$115))
B74: 9 | C74: =IF('INPUT DATA'!Q19="","",'INPUT DATA'!Q19) | F74: =IF('INPUT DATA'!T19="","",'INPUT DATA'!T19) | H74: =IF('INPUT DATA'!S19="","",'INPUT DATA'!S19) | I74: =IF(H74="","",DATEDIF(H74,TODAY(),"Y")) | T74: =IF(COUNT(K74:S74)=0,"",ROUND((K74+L74+M74+N74+O74+S74)/6,0)) | U74: =IF(T74="","",_xlfn.RANK.AVG(T74,$T$15:$T$115))
B75: 10 | C75: =IF('INPUT DATA'!Q20="","",'INPUT DATA'!Q20) | F75: =IF('INPUT DATA'!T20="","",'INPUT DATA'!T20) | H75: =IF('INPUT DATA'!S20="","",'INPUT DATA'!S20) | I75: =IF(H75="","",DATEDIF(H75,TODAY(),"Y")) | T75: =IF(COUNT(K75:S75)=0,"",ROUND((K75+L75+M75+N75+O75+S75)/6,0)) | U75: =IF(T75="","",_xlfn.RANK.AVG(T75,$T$15:$T$115))
B76: 11 | C76: =IF('INPUT DATA'!Q21="","",'INPUT DATA'!Q21) | F76: =IF('INPUT DATA'!T21="","",'INPUT DATA'!T21) | H76: =IF('INPUT DATA'!S21="","",'INPUT DATA'!S21) | I76: =IF(H76="","",DATEDIF(H76,TODAY(),"Y")) | T76: =IF(COUNT(K76:S76)=0,"",ROUND((K76+L76+M76+N76+O76+S76)/6,0)) | U76: =IF(T76="","",_xlfn.RANK.AVG(T76,$T$15:$T$115))
B77: 12 | C77: =IF('INPUT DATA'!Q22="","",'INPUT DATA'!Q22) | F77: =IF('INPUT DATA'!T22="","",'INPUT DATA'!T22) | H77: =IF('INPUT DATA'!S22="","",'INPUT DATA'!S22) | I77: =IF(H77="","",DATEDIF(H77,TODAY(),"Y")) | T77: =IF(COUNT(K77:S77)=0,"",ROUND((K77+L77+M77+N77+O77+S77)/6,0)) | U77: =IF(T77="","",_xlfn.RANK.AVG(T77,$T$15:$T$115))
B78: 13 | C78: =IF('INPUT DATA'!Q23="","",'INPUT DATA'!Q23) | F78: =IF('INPUT DATA'!T23="","",'INPUT DATA'!T23) | H78: =IF('INPUT DATA'!S23="","",'INPUT DATA'!S23) | I78: =IF(H78="","",DATEDIF(H78,TODAY(),"Y")) | T78: =IF(COUNT(K78:S78)=0,"",ROUND((K78+L78+M78+N78+O78+S78)/6,0)) | U78: =IF(T78="","",_xlfn.RANK.AVG(T78,$T$15:$T$115))
B79: 14 | C79: =IF('INPUT DATA'!Q24="","",'INPUT DATA'!Q24) | F79: =IF('INPUT DATA'!T24="","",'INPUT DATA'!T24) | H79: =IF('INPUT DATA'!S24="","",'INPUT DATA'!S24) | I79: =IF(H79="","",DATEDIF(H79,TODAY(),"Y")) | T79: =IF(COUNT(K79:S79)=0,"",ROUND((K79+L79+M79+N79+O79+S79)/6,0)) | U79: =IF(T79="","",_xlfn.RANK.AVG(T79,$T$15:$T$115))
B80: 15 | C80: =IF('INPUT DATA'!Q25="","",'INPUT DATA'!Q25) | F80: =IF('INPUT DATA'!T25="","",'INPUT DATA'!T25) | H80: =IF('INPUT DATA'!S25="","",'INPUT DATA'!S25) | I80: =IF(H80="","",DATEDIF(H80,TODAY(),"Y")) | T80: =IF(COUNT(K80:S80)=0,"",ROUND((K80+L80+M80+N80+O80+S80)/6,0)) | U80: =IF(T80="","",_xlfn.RANK.AVG(T80,$T$15:$T$115))
...

Sheet TERM 2 SUMMARY A
A1: CLASS SUMMARY - TERM 2
D5: REGION | E5: ='TERM 1 SUMMARY'!E5:G5 -> NCR | I5: DIVISION | K5: ='TERM 1 SUMMARY'!K5:M5 -> LAS PINAS
D6: SCHOOL NAME | E6: ='TERM 1 SUMMARY'!E6:G6 -> LAS PINAS EAST NATIONAL HIGH SCHOOL | I6: SCHOOL ID | K6: ='TERM 1 SUMMARY'!K6:M6 -> 305434 | S6: SCHOOL YEAR | T6: ='TERM 1 SUMMARY'!T6:U6 -> 2026-2027
B9: SECOND TERM | F9: GRADE LEVEL | G9: ='TERM 1 SUMMARY'!G9:K9 -> 10 | L9: ADVISER | N9: ='TERM 1 SUMMARY'!N9:U10 -> #VALUE!
F10: SECTION | G10: ='TERM 1 SUMMARY'!G10:K10 -> PAMAYPAY
B11: LEARNERS' NAMES | F11: LRN | H11: Date of Birth | I11: Age | J11: Sex | K11: Learning Areas | T11: Final Grade | U11: Rank
K12: Filipino | L12: English | M12: Mathematics | N12: Science | O12: AP | P12: GMRC/VE | Q12: EPP/TLE | R12: MAPEH
R13: M A | S13: P E H
B15: 1 | C15: =IF('INPUT DATA'!L11="","",'INPUT DATA'!L11) -> A | F15: =IF('INPUT DATA'!M11="","",'INPUT DATA'!M11) -> 123456789012 | H15: =IF('INPUT DATA'!N11="","",'INPUT DATA'!N11) -> 40355 | I15: =IF(H15="","",DATEDIF(H15,TODAY(),"Y")) -> 16 | J15: M | T15: =IF(COUNT(K15:S15)=0,"",ROUND((K15+L15+M15+N15+O15+S15)/6,0)) | U15: =IF(T15="","",_xlfn.RANK.AVG(T15,$T$15:$T$115))
B16: 2 | C16: =IF('INPUT DATA'!L12="","",'INPUT DATA'!L12) -> B | F16: =IF('INPUT DATA'!M12="","",'INPUT DATA'!M12) -> 2 | H16: =IF('INPUT DATA'!N12="","",'INPUT DATA'!N12) -> 40574 | I16: =IF(H16="","",DATEDIF(H16,TODAY(),"Y")) -> 15 | J16: M | T16: =IF(COUNT(K16:S16)=0,"",ROUND((K16+L16+M16+N16+O16+S16)/6,0)) | U16: =IF(T16="","",_xlfn.RANK.AVG(T16,$T$15:$T$115))
B17: 3 | C17: =IF('INPUT DATA'!L13="","",'INPUT DATA'!L13) | F17: =IF('INPUT DATA'!M13="","",'INPUT DATA'!M13) | H17: =IF('INPUT DATA'!N13="","",'INPUT DATA'!N13) | I17: =IF(H17="","",DATEDIF(H17,TODAY(),"Y")) | J17: M | T17: =IF(COUNT(K17:S17)=0,"",ROUND((K17+L17+M17+N17+O17+S17)/6,0)) | U17: =IF(T17="","",_xlfn.RANK.AVG(T17,$T$15:$T$115))
B18: 4 | C18: =IF('INPUT DATA'!L14="","",'INPUT DATA'!L14) | F18: =IF('INPUT DATA'!M14="","",'INPUT DATA'!M14) | H18: =IF('INPUT DATA'!N14="","",'INPUT DATA'!N14) | I18: =IF(H18="","",DATEDIF(H18,TODAY(),"Y")) | T18: =IF(COUNT(K18:S18)=0,"",ROUND((K18+L18+M18+N18+O18+S18)/6,0)) | U18: =IF(T18="","",_xlfn.RANK.AVG(T18,$T$15:$T$115))
B19: 5 | C19: =IF('INPUT DATA'!L15="","",'INPUT DATA'!L15) | F19: =IF('INPUT DATA'!M15="","",'INPUT DATA'!M15) | H19: =IF('INPUT DATA'!N15="","",'INPUT DATA'!N15) | I19: =IF(H19="","",DATEDIF(H19,TODAY(),"Y")) | T19: =IF(COUNT(K19:S19)=0,"",ROUND((K19+L19+M19+N19+O19+S19)/6,0)) | U19: =IF(T19="","",_xlfn.RANK.AVG(T19,$T$15:$T$115))
B20: 6 | C20: =IF('INPUT DATA'!L16="","",'INPUT DATA'!L16) | F20: =IF('INPUT DATA'!M16="","",'INPUT DATA'!M16) | H20: =IF('INPUT DATA'!N16="","",'INPUT DATA'!N16) | I20: =IF(H20="","",DATEDIF(H20,TODAY(),"Y")) | T20: =IF(COUNT(K20:S20)=0,"",ROUND((K20+L20+M20+N20+O20+S20)/6,0)) | U20: =IF(T20="","",_xlfn.RANK.AVG(T20,$T$15:$T$115))
B21: 7 | C21: =IF('INPUT DATA'!L17="","",'INPUT DATA'!L17) | F21: =IF('INPUT DATA'!M17="","",'INPUT DATA'!M17) | H21: =IF('INPUT DATA'!N17="","",'INPUT DATA'!N17) | I21: =IF(H21="","",DATEDIF(H21,TODAY(),"Y")) | T21: =IF(COUNT(K21:S21)=0,"",ROUND((K21+L21+M21+N21+O21+S21)/6,0)) | U21: =IF(T21="","",_xlfn.RANK.AVG(T21,$T$15:$T$115))
B22: 8 | C22: =IF('INPUT DATA'!L18="","",'INPUT DATA'!L18) | F22: =IF('INPUT DATA'!M18="","",'INPUT DATA'!M18) | H22: =IF('INPUT DATA'!N18="","",'INPUT DATA'!N18) | I22: =IF(H22="","",DATEDIF(H22,TODAY(),"Y")) | T22: =IF(COUNT(K22:S22)=0,"",ROUND((K22+L22+M22+N22+O22+S22)/6,0)) | U22: =IF(T22="","",_xlfn.RANK.AVG(T22,$T$15:$T$115))
B23: 9 | C23: =IF('INPUT DATA'!L19="","",'INPUT DATA'!L19) | F23: =IF('INPUT DATA'!M19="","",'INPUT DATA'!M19) | H23: =IF('INPUT DATA'!N19="","",'INPUT DATA'!N19) | I23: =IF(H23="","",DATEDIF(H23,TODAY(),"Y")) | T23: =IF(COUNT(K23:S23)=0,"",ROUND((K23+L23+M23+N23+O23+S23)/6,0)) | U23: =IF(T23="","",_xlfn.RANK.AVG(T23,$T$15:$T$115))
B24: 10 | C24: =IF('INPUT DATA'!L20="","",'INPUT DATA'!L20) | F24: =IF('INPUT DATA'!M20="","",'INPUT DATA'!M20) | H24: =IF('INPUT DATA'!N20="","",'INPUT DATA'!N20) | I24: =IF(H24="","",DATEDIF(H24,TODAY(),"Y")) | T24: =IF(COUNT(K24:S24)=0,"",ROUND((K24+L24+M24+N24+O24+S24)/6,0)) | U24: =IF(T24="","",_xlfn.RANK.AVG(T24,$T$15:$T$115))
B25: 11 | C25: =IF('INPUT DATA'!L21="","",'INPUT DATA'!L21) | F25: =IF('INPUT DATA'!M21="","",'INPUT DATA'!M21) | H25: =IF('INPUT DATA'!N21="","",'INPUT DATA'!N21) | I25: =IF(H25="","",DATEDIF(H25,TODAY(),"Y")) | T25: =IF(COUNT(K25:S25)=0,"",ROUND((K25+L25+M25+N25+O25+S25)/6,0)) | U25: =IF(T25="","",_xlfn.RANK.AVG(T25,$T$15:$T$115))
B26: 12 | C26: =IF('INPUT DATA'!L22="","",'INPUT DATA'!L22) | F26: =IF('INPUT DATA'!M22="","",'INPUT DATA'!M22) | H26: =IF('INPUT DATA'!N22="","",'INPUT DATA'!N22) | I26: =IF(H26="","",DATEDIF(H26,TODAY(),"Y")) | T26: =IF(COUNT(K26:S26)=0,"",ROUND((K26+L26+M26+N26+O26+S26)/6,0)) | U26: =IF(T26="","",_xlfn.RANK.AVG(T26,$T$15:$T$115))
B27: 13 | C27: =IF('INPUT DATA'!L23="","",'INPUT DATA'!L23) | F27: =IF('INPUT DATA'!M23="","",'INPUT DATA'!M23) | H27: =IF('INPUT DATA'!N23="","",'INPUT DATA'!N23) | I27: =IF(H27="","",DATEDIF(H27,TODAY(),"Y")) | T27: =IF(COUNT(K27:S27)=0,"",ROUND((K27+L27+M27+N27+O27+S27)/6,0)) | U27: =IF(T27="","",_xlfn.RANK.AVG(T27,$T$15:$T$115))
B28: 14 | C28: =IF('INPUT DATA'!L24="","",'INPUT DATA'!L24) | F28: =IF('INPUT DATA'!M24="","",'INPUT DATA'!M24) | H28: =IF('INPUT DATA'!N24="","",'INPUT DATA'!N24) | I28: =IF(H28="","",DATEDIF(H28,TODAY(),"Y")) | T28: =IF(COUNT(K28:S28)=0,"",ROUND((K28+L28+M28+N28+O28+S28)/6,0)) | U28: =IF(T28="","",_xlfn.RANK.AVG(T28,$T$15:$T$115))
B29: 15 | C29: =IF('INPUT DATA'!L25="","",'INPUT DATA'!L25) | F29: =IF('INPUT DATA'!M25="","",'INPUT DATA'!M25) | H29: =IF('INPUT DATA'!N25="","",'INPUT DATA'!N25) | I29: =IF(H29="","",DATEDIF(H29,TODAY(),"Y")) | T29: =IF(COUNT(K29:S29)=0,"",ROUND((K29+L29+M29+N29+O29+S29)/6,0)) | U29: =IF(T29="","",_xlfn.RANK.AVG(T29,$T$15:$T$115))
... B64: 50 | C64: =IF('INPUT DATA'!L60="","",'INPUT DATA'!L60) | F64: =IF('INPUT DATA'!M60="","",'INPUT DATA'!M60) | H64: =IF('INPUT DATA'!N60="","",'INPUT DATA'!N60) | I64: =IF(H64="","",DATEDIF(H64,TODAY(),"Y")) | T64: =IF(COUNT(K64:S64)=0,"",ROUND((K64+L64+M64+N64+O64+S64)/6,0)) | U64: =IF(T64="","",_xlfn.RANK.AVG(T64,$T$15:$T$115))
B65: FEMALE
B66: 1 | C66: =IF('INPUT DATA'!Q11="","",'INPUT DATA'!Q11) | F66: =IF('INPUT DATA'!T11="","",'INPUT DATA'!T11) | H66: =IF('INPUT DATA'!S11="","",'INPUT DATA'!S11) | I66: =IF(H66="","",DATEDIF(H66,TODAY(),"Y")) | J66: F | T66: =IF(COUNT(K66:S66)=0,"",ROUND((K66+L66+M66+N66+O66+S66)/6,0)) | U66: =IF(T66="","",_xlfn.RANK.AVG(T66,$T$15:$T$115))
B67: 2 | C67: =IF('INPUT DATA'!Q12="","",'INPUT DATA'!Q12) | F67: =IF('INPUT DATA'!T12="","",'INPUT DATA'!T12) | H67: =IF('INPUT DATA'!S12="","",'INPUT DATA'!S12) | I67: =IF(H67="","",DATEDIF(H67,TODAY(),"Y")) | J67: F | T67: =IF(COUNT(K67:S67)=0,"",ROUND((K67+L67+M67+N67+O67+S67)/6,0)) | U67: =IF(T67="","",_xlfn.RANK.AVG(T67,$T$15:$T$115))
B68: 3 | C68: =IF('INPUT DATA'!Q13="","",'INPUT DATA'!Q13) | F68: =IF('INPUT DATA'!T13="","",'INPUT DATA'!T13) | H68: =IF('INPUT DATA'!S13="","",'INPUT DATA'!S13) | I68: =IF(H68="","",DATEDIF(H68,TODAY(),"Y")) | J68: F | T68: =IF(COUNT(K68:S68)=0,"",ROUND((K68+L68+M68+N68+O68+S68)/6,0)) | U68: =IF(T68="","",_xlfn.RANK.AVG(T68,$T$15:$T$115))
B69: 4 | C69: =IF('INPUT DATA'!Q14="","",'INPUT DATA'!Q14) | F69: =IF('INPUT DATA'!T14="","",'INPUT DATA'!T14) | H69: =IF('INPUT DATA'!S14="","",'INPUT DATA'!S14) | I69: =IF(H69="","",DATEDIF(H69,TODAY(),"Y")) | T69: =IF(COUNT(K69:S69)=0,"",ROUND((K69+L69+M69+N69+O69+S69)/6,0)) | U69: =IF(T69="","",_xlfn.RANK.AVG(T69,$T$15:$T$115))
B70: 5 | C70: =IF('INPUT DATA'!Q15="","",'INPUT DATA'!Q15) | F70: =IF('INPUT DATA'!T15="","",'INPUT DATA'!T15) | H70: =IF('INPUT DATA'!S15="","",'INPUT DATA'!S15) | I70: =IF(H70="","",DATEDIF(H70,TODAY(),"Y")) | T70: =IF(COUNT(K70:S70)=0,"",ROUND((K70+L70+M70+N70+O70+S70)/6,0)) | U70: =IF(T70="","",_xlfn.RANK.AVG(T70,$T$15:$T$115))
B71: 6 | C71: =IF('INPUT DATA'!Q16="","",'INPUT DATA'!Q16) | F71: =IF('INPUT DATA'!T16="","",'INPUT DATA'!T16) | H71: =IF('INPUT DATA'!S16="","",'INPUT DATA'!S16) | I71: =IF(H71="","",DATEDIF(H71,TODAY(),"Y")) | T71: =IF(COUNT(K71:S71)=0,"",ROUND((K71+L71+M71+N71+O71+S71)/6,0)) | U71: =IF(T71="","",_xlfn.RANK.AVG(T71,$T$15:$T$115))
B72: 7 | C72: =IF('INPUT DATA'!Q17="","",'INPUT DATA'!Q17) | F72: =IF('INPUT DATA'!T17="","",'INPUT DATA'!T17) | H72: =IF('INPUT DATA'!S17="","",'INPUT DATA'!S17) | I72: =IF(H72="","",DATEDIF(H72,TODAY(),"Y")) | T72: =IF(COUNT(K72:S72)=0,"",ROUND((K72+L72+M72+N72+O72+S72)/6,0)) | U72: =IF(T72="","",_xlfn.RANK.AVG(T72,$T$15:$T$115))
B73: 8 | C73: =IF('INPUT DATA'!Q18="","",'INPUT DATA'!Q18) | F73: =IF('INPUT DATA'!T18="","",'INPUT DATA'!T18) | H73: =IF('INPUT DATA'!S18="","",'INPUT DATA'!S18) | I73: =IF(H73="","",DATEDIF(H73,TODAY(),"Y")) | T73: =IF(COUNT(K73:S73)=0,"",ROUND((K73+L73+M73+N73+O73+S73)/6,0)) | U73: =IF(T73="","",_xlfn.RANK.AVG(T73,$T$15:$T$115))
B74: 9 | C74: =IF('INPUT DATA'!Q19="","",'INPUT DATA'!Q19) | F74: =IF('INPUT DATA'!T19="","",'INPUT DATA'!T19) | H74: =IF('INPUT DATA'!S19="","",'INPUT DATA'!S19) | I74: =IF(H74="","",DATEDIF(H74,TODAY(),"Y")) | T74: =IF(COUNT(K74:S74)=0,"",ROUND((K74+L74+M74+N74+O74+S74)/6,0)) | U74: =IF(T74="","",_xlfn.RANK.AVG(T74,$T$15:$T$115))
B75: 10 | C75: =IF('INPUT DATA'!Q20="","",'INPUT DATA'!Q20) | F75: =IF('INPUT DATA'!T20="","",'INPUT DATA'!T20) | H75: =IF('INPUT DATA'!S20="","",'INPUT DATA'!S20) | I75: =IF(H75="","",DATEDIF(H75,TODAY(),"Y")) | T75: =IF(COUNT(K75:S75)=0,"",ROUND((K75+L75+M75+N75+O75+S75)/6,0)) | U75: =IF(T75="","",_xlfn.RANK.AVG(T75,$T$15:$T$115))
B76: 11 | C76: =IF('INPUT DATA'!Q21="","",'INPUT DATA'!Q21) | F76: =IF('INPUT DATA'!T21="","",'INPUT DATA'!T21) | H76: =IF('INPUT DATA'!S21="","",'INPUT DATA'!S21) | I76: =IF(H76="","",DATEDIF(H76,TODAY(),"Y")) | T76: =IF(COUNT(K76:S76)=0,"",ROUND((K76+L76+M76+N76+O76+S76)/6,0)) | U76: =IF(T76="","",_xlfn.RANK.AVG(T76,$T$15:$T$115))
B77: 12 | C77: =IF('INPUT DATA'!Q22="","",'INPUT DATA'!Q22) | F77: =IF('INPUT DATA'!T22="","",'INPUT DATA'!T22) | H77: =IF('INPUT DATA'!S22="","",'INPUT DATA'!S22) | I77: =IF(H77="","",DATEDIF(H77,TODAY(),"Y")) | T77: =IF(COUNT(K77:S77)=0,"",ROUND((K77+L77+M77+N77+O77+S77)/6,0)) | U77: =IF(T77="","",_xlfn.RANK.AVG(T77,$T$15:$T$115))
B78: 13 | C78: =IF('INPUT DATA'!Q23="","",'INPUT DATA'!Q23) | F78: =IF('INPUT DATA'!T23="","",'INPUT DATA'!T23) | H78: =IF('INPUT DATA'!S23="","",'INPUT DATA'!S23) | I78: =IF(H78="","",DATEDIF(H78,TODAY(),"Y")) | T78: =IF(COUNT(K78:S78)=0,"",ROUND((K78+L78+M78+N78+O78+S78)/6,0)) | U78: =IF(T78="","",_xlfn.RANK.AVG(T78,$T$15:$T$115))
B79: 14 | C79: =IF('INPUT DATA'!Q24="","",'INPUT DATA'!Q24) | F79: =IF('INPUT DATA'!T24="","",'INPUT DATA'!T24) | H79: =IF('INPUT DATA'!S24="","",'INPUT DATA'!S24) | I79: =IF(H79="","",DATEDIF(H79,TODAY(),"Y")) | T79: =IF(COUNT(K79:S79)=0,"",ROUND((K79+L79+M79+N79+O79+S79)/6,0)) | U79: =IF(T79="","",_xlfn.RANK.AVG(T79,$T$15:$T$115))
B80: 15 | C80: =IF('INPUT DATA'!Q25="","",'INPUT DATA'!Q25) | F80: =IF('INPUT DATA'!T25="","",'INPUT DATA'!T25) | H80: =IF('INPUT DATA'!S25="","",'INPUT DATA'!S25) | I80: =IF(H80="","",DATEDIF(H80,TODAY(),"Y")) | T80: =IF(COUNT(K80:S80)=0,"",ROUND((K80+L80+M80+N80+O80+S80)/6,0)) | U80: =IF(T80="","",_xlfn.RANK.AVG(T80,$T$15:$T$115))
...

Sheet TERM 3 SUMMARY
A1: CLASS SUMMARY - TERM 3
D5: REGION | E5: ='INPUT DATA'!F10 -> NCR | I5: DIVISION | K5: ='INPUT DATA'!F11 -> LAS PINAS
D6: SCHOOL NAME | E6: ='INPUT DATA'!F16 -> LAS PINAS EAST NATIONAL HIGH SCHOOL | I6: SCHOOL ID | K6: ='INPUT DATA'!F15 -> 305434 | S6: SCHOOL YEAR | T6: ='INPUT DATA'!F18 -> 2026-2027
B9: THIRD TERM | F9: GRADE LEVEL | G9: ='INPUT DATA'!F27 -> 10 | L9: ADVISER | N9: ='INPUT DATA'!F26 -> ROSALINDA S. VALE
F10: SECTION | G10: ='INPUT DATA'!F28 -> PAMAYPAY
B11: LEARNERS' NAMES | F11: LRN | H11: Date of Birth | I11: Age | J11: Sex | K11: Learning Areas | T11: Final Grade | U11: Rank
K12: Filipino | L12: English | M12: Mathematics | N12: Science | O12: AP | P12: GMRC/VE | Q12: EPP/TLE | R12: MAPEH
R13: M A | S13: P E H
B15: 1 | C15: =IF('INPUT DATA'!L11="","",'INPUT DATA'!L11) -> A | F15: =IF('INPUT DATA'!M11="","",'INPUT DATA'!M11) -> 123456789012 | H15: =IF('INPUT DATA'!N11="","",'INPUT DATA'!N11) -> 40355 | I15: =IF(H15="","",DATEDIF(H15,TODAY(),"Y")) -> 16 | J15: M | K15: 91 | L15: 90 | M15: 92 | N15: 90 | O15: 91 | P15: 92 | Q15: 91 | R15: 92 | S15: 92 | T15: =IF(COUNT(K15:S15)=0,"",ROUND((K15+L15+M15+N15+O15+S15)/6,0)) -> 91 | U15: =IF(T15="","",_xlfn.RANK.AVG(T15,$T$15:$T$115)) -> 2.5
B16: 2 | C16: =IF('INPUT DATA'!L12="","",'INPUT DATA'!L12) -> B | F16: =IF('INPUT DATA'!M12="","",'INPUT DATA'!M12) -> 2 | H16: =IF('INPUT DATA'!N12="","",'INPUT DATA'!N12) -> 40574 | I16: =IF(H16="","",DATEDIF(H16,TODAY(),"Y")) -> 15 | J16: M | K16: 90 | L16: 93 | M16: 89 | N16: 90 | O16: 88 | P16: 90 | Q16: 91 | R16: 90 | S16: 90 | T16: =IF(COUNT(K16:S16)=0,"",ROUND((K16+L16+M16+N16+O16+S16)/6,0)) -> 90 | U16: =IF(T16="","",_xlfn.RANK.AVG(T16,$T$15:$T$115)) -> 5
B17: 3 | C17: =IF('INPUT DATA'!L13="","",'INPUT DATA'!L13) | F17: =IF('INPUT DATA'!M13="","",'INPUT DATA'!M13) | H17: =IF('INPUT DATA'!N13="","",'INPUT DATA'!N13) | I17: =IF(H17="","",DATEDIF(H17,TODAY(),"Y")) | J17: M | K17: 92 | L17: 89 | M17: 87 | N17: 90 | O17: 84 | P17: 86 | Q17: 91 | R17: 86 | S17: 86 | T17: =IF(COUNT(K17:S17)=0,"",ROUND((K17+L17+M17+N17+O17+S17)/6,0)) -> 88 | U17: =IF(T17="","",_xlfn.RANK.AVG(T17,$T$15:$T$115)) -> 6
B18: 4 | C18: =IF('INPUT DATA'!L14="","",'INPUT DATA'!L14) | F18: =IF('INPUT DATA'!M14="","",'INPUT DATA'!M14) | H18: =IF('INPUT DATA'!N14="","",'INPUT DATA'!N14) | I18: =IF(H18="","",DATEDIF(H18,TODAY(),"Y")) | T18: =IF(COUNT(K18:S18)=0,"",ROUND((K18+L18+M18+N18+O18+S18)/6,0)) | U18: =IF(T18="","",_xlfn.RANK.AVG(T18,$T$15:$T$115))
B19: 5 | C19: =IF('INPUT DATA'!L15="","",'INPUT DATA'!L15) | F19: =IF('INPUT DATA'!M15="","",'INPUT DATA'!M15) | H19: =IF('INPUT DATA'!N15="","",'INPUT DATA'!N15) | I19: =IF(H19="","",DATEDIF(H19,TODAY(),"Y")) | T19: =IF(COUNT(K19:S19)=0,"",ROUND((K19+L19+M19+N19+O19+S19)/6,0)) | U19: =IF(T19="","",_xlfn.RANK.AVG(T19,$T$15:$T$115))
B20: 6 | C20: =IF('INPUT DATA'!L16="","",'INPUT DATA'!L16) | F20: =IF('INPUT DATA'!M16="","",'INPUT DATA'!M16) | H20: =IF('INPUT DATA'!N16="","",'INPUT DATA'!N16) | I20: =IF(H20="","",DATEDIF(H20,TODAY(),"Y")) | T20: =IF(COUNT(K20:S20)=0,"",ROUND((K20+L20+M20+N20+O20+S20)/6,0)) | U20: =IF(T20="","",_xlfn.RANK.AVG(T20,$T$15:$T$115))
B21: 7 | C21: =IF('INPUT DATA'!L17="","",'INPUT DATA'!L17) | F21: =IF('INPUT DATA'!M17="","",'INPUT DATA'!M17) | H21: =IF('INPUT DATA'!N17="","",'INPUT DATA'!N17) | I21: =IF(H21="","",DATEDIF(H21,TODAY(),"Y")) | T21: =IF(COUNT(K21:S21)=0,"",ROUND((K21+L21+M21+N21+O21+S21)/6,0)) | U21: =IF(T21="","",_xlfn.RANK.AVG(T21,$T$15:$T$115))
B22: 8 | C22: =IF('INPUT DATA'!L18="","",'INPUT DATA'!L18) | F22: =IF('INPUT DATA'!M18="","",'INPUT DATA'!M18) | H22: =IF('INPUT DATA'!N18="","",'INPUT DATA'!N18) | I22: =IF(H22="","",DATEDIF(H22,TODAY(),"Y")) | T22: =IF(COUNT(K22:S22)=0,"",ROUND((K22+L22+M22+N22+O22+S22)/6,0)) | U22: =IF(T22="","",_xlfn.RANK.AVG(T22,$T$15:$T$115))
B23: 9 | C23: =IF('INPUT DATA'!L19="","",'INPUT DATA'!L19) | F23: =IF('INPUT DATA'!M19="","",'INPUT DATA'!M19) | H23: =IF('INPUT DATA'!N19="","",'INPUT DATA'!N19) | I23: =IF(H23="","",DATEDIF(H23,TODAY(),"Y")) | T23: =IF(COUNT(K23:S23)=0,"",ROUND((K23+L23+M23+N23+O23+S23)/6,0)) | U23: =IF(T23="","",_xlfn.RANK.AVG(T23,$T$15:$T$115))
B24: 10 | C24: =IF('INPUT DATA'!L20="","",'INPUT DATA'!L20) | F24: =IF('INPUT DATA'!M20="","",'INPUT DATA'!M20) | H24: =IF('INPUT DATA'!N20="","",'INPUT DATA'!N20) | I24: =IF(H24="","",DATEDIF(H24,TODAY(),"Y")) | T24: =IF(COUNT(K24:S24)=0,"",ROUND((K24+L24+M24+N24+O24+S24)/6,0)) | U24: =IF(T24="","",_xlfn.RANK.AVG(T24,$T$15:$T$115))
B25: 11 | C25: =IF('INPUT DATA'!L21="","",'INPUT DATA'!L21) | F25: =IF('INPUT DATA'!M21="","",'INPUT DATA'!M21) | H25: =IF('INPUT DATA'!N21="","",'INPUT DATA'!N21) | I25: =IF(H25="","",DATEDIF(H25,TODAY(),"Y")) | T25: =IF(COUNT(K25:S25)=0,"",ROUND((K25+L25+M25+N25+O25+S25)/6,0)) | U25: =IF(T25="","",_xlfn.RANK.AVG(T25,$T$15:$T$115))
B26: 12 | C26: =IF('INPUT DATA'!L22="","",'INPUT DATA'!L22) | F26: =IF('INPUT DATA'!M22="","",'INPUT DATA'!M22) | H26: =IF('INPUT DATA'!N22="","",'INPUT DATA'!N22) | I26: =IF(H26="","",DATEDIF(H26,TODAY(),"Y")) | T26: =IF(COUNT(K26:S26)=0,"",ROUND((K26+L26+M26+N26+O26+S26)/6,0)) | U26: =IF(T26="","",_xlfn.RANK.AVG(T26,$T$15:$T$115))
B27: 13 | C27: =IF('INPUT DATA'!L23="","",'INPUT DATA'!L23) | F27: =IF('INPUT DATA'!M23="","",'INPUT DATA'!M23) | H27: =IF('INPUT DATA'!N23="","",'INPUT DATA'!N23) | I27: =IF(H27="","",DATEDIF(H27,TODAY(),"Y")) | T27: =IF(COUNT(K27:S27)=0,"",ROUND((K27+L27+M27+N27+O27+S27)/6,0)) | U27: =IF(T27="","",_xlfn.RANK.AVG(T27,$T$15:$T$115))
B28: 14 | C28: =IF('INPUT DATA'!L24="","",'INPUT DATA'!L24) | F28: =IF('INPUT DATA'!M24="","",'INPUT DATA'!M24) | H28: =IF('INPUT DATA'!N24="","",'INPUT DATA'!N24) | I28: =IF(H28="","",DATEDIF(H28,TODAY(),"Y")) | T28: =IF(COUNT(K28:S28)=0,"",ROUND((K28+L28+M28+N28+O28+S28)/6,0)) | U28: =IF(T28="","",_xlfn.RANK.AVG(T28,$T$15:$T$115))
B29: 15 | C29: =IF('INPUT DATA'!L25="","",'INPUT DATA'!L25) | F29: =IF('INPUT DATA'!M25="","",'INPUT DATA'!M25) | H29: =IF('INPUT DATA'!N25="","",'INPUT DATA'!N25) | I29: =IF(H29="","",DATEDIF(H29,TODAY(),"Y")) | T29: =IF(COUNT(K29:S29)=0,"",ROUND((K29+L29+M29+N29+O29+S29)/6,0)) | U29: =IF(T29="","",_xlfn.RANK.AVG(T29,$T$15:$T$115))
... B64: 50 | C64: =IF('INPUT DATA'!L60="","",'INPUT DATA'!L60) | F64: =IF('INPUT DATA'!M60="","",'INPUT DATA'!M60) | H64: =IF('INPUT DATA'!N60="","",'INPUT DATA'!N60) | I64: =IF(H64="","",DATEDIF(H64,TODAY(),"Y")) | T64: =IF(COUNT(K64:S64)=0,"",ROUND((K64+L64+M64+N64+O64+S64)/6,0)) | U64: =IF(T64="","",_xlfn.RANK.AVG(T64,$T$15:$T$115))
B65: FEMALE
B66: 1 | C66: =IF('INPUT DATA'!Q11="","",'INPUT DATA'!Q11) | F66: ='INPUT DATA'!R11 | H66: =IF('INPUT DATA'!S11="","",'INPUT DATA'!S11) | I66: =IF(H66="","",DATEDIF(H66,TODAY(),"Y")) | J66: F | K66: 90 | L66: 91 | M66: 89 | N66: 90 | O66: 91 | S66: 92 | T66: =IF(COUNT(K66:S66)=0,"",ROUND((K66+L66+M66+N66+O66+S66)/6,0)) -> 91 | U66: =IF(T66="","",_xlfn.RANK.AVG(T66,$T$15:$T$115)) -> 2.5
B67: 2 | C67: =IF('INPUT DATA'!Q12="","",'INPUT DATA'!Q12) | F67: ='INPUT DATA'!R12 | H67: =IF('INPUT DATA'!S12="","",'INPUT DATA'!S12) | I67: =IF(H67="","",DATEDIF(H67,TODAY(),"Y")) | J67: F | K67: 92 | L67: 93 | M67: 89 | N67: 90 | O67: 90 | S67: 90 | T67: =IF(COUNT(K67:S67)=0,"",ROUND((K67+L67+M67+N67+O67+S67)/6,0)) -> 91 | U67: =IF(T67="","",_xlfn.RANK.AVG(T67,$T$15:$T$115)) -> 2.5
B68: 3 | C68: =IF('INPUT DATA'!Q13="","",'INPUT DATA'!Q13) | F68: ='INPUT DATA'!R13 | H68: =IF('INPUT DATA'!S13="","",'INPUT DATA'!S13) | I68: =IF(H68="","",DATEDIF(H68,TODAY(),"Y")) | J68: F | K68: 91 | L68: 92 | M68: 91 | N68: 90 | O68: 92 | S68: 89 | T68: =IF(COUNT(K68:S68)=0,"",ROUND((K68+L68+M68+N68+O68+S68)/6,0)) -> 91 | U68: =IF(T68="","",_xlfn.RANK.AVG(T68,$T$15:$T$115)) -> 2.5
B69: 4 | C69: =IF('INPUT DATA'!Q14="","",'INPUT DATA'!Q14) | F69: =IF('INPUT DATA'!T14="","",'INPUT DATA'!T14) | H69: =IF('INPUT DATA'!S14="","",'INPUT DATA'!S14) | I69: =IF(H69="","",DATEDIF(H69,TODAY(),"Y")) | T69: =IF(COUNT(K69:S69)=0,"",ROUND((K69+L69+M69+N69+O69+S69)/6,0)) | U69: =IF(T69="","",_xlfn.RANK.AVG(T69,$T$15:$T$115))
B70: 5 | C70: =IF('INPUT DATA'!Q15="","",'INPUT DATA'!Q15) | F70: =IF('INPUT DATA'!T15="","",'INPUT DATA'!T15) | H70: =IF('INPUT DATA'!S15="","",'INPUT DATA'!S15) | I70: =IF(H70="","",DATEDIF(H70,TODAY(),"Y")) | T70: =IF(COUNT(K70:S70)=0,"",ROUND((K70+L70+M70+N70+O70+S70)/6,0)) | U70: =IF(T70="","",_xlfn.RANK.AVG(T70,$T$15:$T$115))
B71: 6 | C71: =IF('INPUT DATA'!Q16="","",'INPUT DATA'!Q16) | F71: =IF('INPUT DATA'!T16="","",'INPUT DATA'!T16) | H71: =IF('INPUT DATA'!S16="","",'INPUT DATA'!S16) | I71: =IF(H71="","",DATEDIF(H71,TODAY(),"Y")) | T71: =IF(COUNT(K71:S71)=0,"",ROUND((K71+L71+M71+N71+O71+S71)/6,0)) | U71: =IF(T71="","",_xlfn.RANK.AVG(T71,$T$15:$T$115))
B72: 7 | C72: =IF('INPUT DATA'!Q17="","",'INPUT DATA'!Q17) | F72: =IF('INPUT DATA'!T17="","",'INPUT DATA'!T17) | H72: =IF('INPUT DATA'!S17="","",'INPUT DATA'!S17) | I72: =IF(H72="","",DATEDIF(H72,TODAY(),"Y")) | T72: =IF(COUNT(K72:S72)=0,"",ROUND((K72+L72+M72+N72+O72+S72)/6,0)) | U72: =IF(T72="","",_xlfn.RANK.AVG(T72,$T$15:$T$115))
B73: 8 | C73: =IF('INPUT DATA'!Q18="","",'INPUT DATA'!Q18) | F73: =IF('INPUT DATA'!T18="","",'INPUT DATA'!T18) | H73: =IF('INPUT DATA'!S18="","",'INPUT DATA'!S18) | I73: =IF(H73="","",DATEDIF(H73,TODAY(),"Y")) | T73: =IF(COUNT(K73:S73)=0,"",ROUND((K73+L73+M73+N73+O73+S73)/6,0)) | U73: =IF(T73="","",_xlfn.RANK.AVG(T73,$T$15:$T$115))
B74: 9 | C74: =IF('INPUT DATA'!Q19="","",'INPUT DATA'!Q19) | F74: =IF('INPUT DATA'!T19="","",'INPUT DATA'!T19) | H74: =IF('INPUT DATA'!S19="","",'INPUT DATA'!S19) | I74: =IF(H74="","",DATEDIF(H74,TODAY(),"Y")) | T74: =IF(COUNT(K74:S74)=0,"",ROUND((K74+L74+M74+N74+O74+S74)/6,0)) | U74: =IF(T74="","",_xlfn.RANK.AVG(T74,$T$15:$T$115))
B75: 10 | C75: =IF('INPUT DATA'!Q20="","",'INPUT DATA'!Q20) | F75: =IF('INPUT DATA'!T20="","",'INPUT DATA'!T20) | H75: =IF('INPUT DATA'!S20="","",'INPUT DATA'!S20) | I75: =IF(H75="","",DATEDIF(H75,TODAY(),"Y")) | T75: =IF(COUNT(K75:S75)=0,"",ROUND((K75+L75+M75+N75+O75+S75)/6,0)) | U75: =IF(T75="","",_xlfn.RANK.AVG(T75,$T$15:$T$115))
B76: 11 | C76: =IF('INPUT DATA'!Q21="","",'INPUT DATA'!Q21) | F76: =IF('INPUT DATA'!T21="","",'INPUT DATA'!T21) | H76: =IF('INPUT DATA'!S21="","",'INPUT DATA'!S21) | I76: =IF(H76="","",DATEDIF(H76,TODAY(),"Y")) | T76: =IF(COUNT(K76:S76)=0,"",ROUND((K76+L76+M76+N76+O76+S76)/6,0)) | U76: =IF(T76="","",_xlfn.RANK.AVG(T76,$T$15:$T$115))
B77: 12 | C77: =IF('INPUT DATA'!Q22="","",'INPUT DATA'!Q22) | F77: =IF('INPUT DATA'!T22="","",'INPUT DATA'!T22) | H77: =IF('INPUT DATA'!S22="","",'INPUT DATA'!S22) | I77: =IF(H77="","",DATEDIF(H77,TODAY(),"Y")) | T77: =IF(COUNT(K77:S77)=0,"",ROUND((K77+L77+M77+N77+O77+S77)/6,0)) | U77: =IF(T77="","",_xlfn.RANK.AVG(T77,$T$15:$T$115))
B78: 13 | C78: =IF('INPUT DATA'!Q23="","",'INPUT DATA'!Q23) | F78: =IF('INPUT DATA'!T23="","",'INPUT DATA'!T23) | H78: =IF('INPUT DATA'!S23="","",'INPUT DATA'!S23) | I78: =IF(H78="","",DATEDIF(H78,TODAY(),"Y")) | T78: =IF(COUNT(K78:S78)=0,"",ROUND((K78+L78+M78+N78+O78+S78)/6,0)) | U78: =IF(T78="","",_xlfn.RANK.AVG(T78,$T$15:$T$115))
B79: 14 | C79: =IF('INPUT DATA'!Q24="","",'INPUT DATA'!Q24) | F79: =IF('INPUT DATA'!T24="","",'INPUT DATA'!T24) | H79: =IF('INPUT DATA'!S24="","",'INPUT DATA'!S24) | I79: =IF(H79="","",DATEDIF(H79,TODAY(),"Y")) | T79: =IF(COUNT(K79:S79)=0,"",ROUND((K79+L79+M79+N79+O79+S79)/6,0)) | U79: =IF(T79="","",_xlfn.RANK.AVG(T79,$T$15:$T$115))
B80: 15 | C80: =IF('INPUT DATA'!Q25="","",'INPUT DATA'!Q25) | F80: =IF('INPUT DATA'!T25="","",'INPUT DATA'!T25) | H80: =IF('INPUT DATA'!S25="","",'INPUT DATA'!S25) | I80: =IF(H80="","",DATEDIF(H80,TODAY(),"Y")) | T80: =IF(COUNT(K80:S80)=0,"",ROUND((K80+L80+M80+N80+O80+S80)/6,0)) | U80: =IF(T80="","",_xlfn.RANK.AVG(T80,$T$15:$T$115))
...

Sheet TERM 3 SUMMARY B
A1: CLASS SUMMARY - TERM 3
D5: REGION | E5: ='TERM 1 SUMMARY'!E5:G5 -> NCR | I5: DIVISION | K5: ='TERM 1 SUMMARY'!K5:M5 -> LAS PINAS
D6: SCHOOL NAME | E6: ='TERM 1 SUMMARY'!E6:G6 -> LAS PINAS EAST NATIONAL HIGH SCHOOL | I6: SCHOOL ID | K6: ='TERM 1 SUMMARY'!K6:M6 -> 305434 | S6: SCHOOL YEAR | T6: ='TERM 1 SUMMARY'!T6:U6 -> 2026-2027
B9: THIRD TERM | F9: GRADE LEVEL | G9: 0 | L9: ADVISER | N9: 0
F10: SECTION | G10: 0
B11: LEARNERS' NAMES | F11: LRN | H11: Date of Birth | I11: Age | J11: Sex | K11: Learning Areas | T11: Final Grade | U11: Rank
K12: Filipino | L12: English | M12: Mathematics | N12: Science | O12: AP | P12: GMRC/VE | Q12: EPP/TLE | R12: MAPEH
R13: M A | S13: P E H
B15: 1 | C15: =IF('INPUT DATA'!L11="","",'INPUT DATA'!L11) -> A | F15: =IF('INPUT DATA'!M11="","",'INPUT DATA'!M11) -> 123456789012 | H15: =IF('INPUT DATA'!N11="","",'INPUT DATA'!N11) -> 40355 | I15: =IF(H15="","",DATEDIF(H15,TODAY(),"Y")) -> 16 | J15: M | T15: =IF(COUNT(K15:S15)=0,"",ROUND((K15+L15+M15+N15+O15+S15)/6,0)) | U15: =IF(T15="","",_xlfn.RANK.AVG(T15,$T$15:$T$115))
B16: 2 | C16: =IF('INPUT DATA'!L12="","",'INPUT DATA'!L12) -> B | J16: M | T16: =IF(COUNT(K16:S16)=0,"",ROUND((K16+L16+M16+N16+O16+S16)/6,0)) | U16: =IF(T16="","",_xlfn.RANK.AVG(T16,$T$15:$T$115))
B17: 3 | C17: =IF('INPUT DATA'!L13="","",'INPUT DATA'!L13) | J17: M | T17: =IF(COUNT(K17:S17)=0,"",ROUND((K17+L17+M17+N17+O17+S17)/6,0)) | U17: =IF(T17="","",_xlfn.RANK.AVG(T17,$T$15:$T$115))
B18: 4 | C18: =IF('INPUT DATA'!L14="","",'INPUT DATA'!L14) | T18: =IF(COUNT(K18:S18)=0,"",ROUND((K18+L18+M18+N18+O18+S18)/6,0)) | U18: =IF(T18="","",_xlfn.RANK.AVG(T18,$T$15:$T$115))
B19: 5 | C19: =IF('INPUT DATA'!L15="","",'INPUT DATA'!L15) | T19: =IF(COUNT(K19:S19)=0,"",ROUND((K19+L19+M19+N19+O19+S19)/6,0)) | U19: =IF(T19="","",_xlfn.RANK.AVG(T19,$T$15:$T$115))
B20: 6 | C20: =IF('INPUT DATA'!L16="","",'INPUT DATA'!L16) | T20: =IF(COUNT(K20:S20)=0,"",ROUND((K20+L20+M20+N20+O20+S20)/6,0)) | U20: =IF(T20="","",_xlfn.RANK.AVG(T20,$T$15:$T$115))
B21: 7 | C21: =IF('INPUT DATA'!L17="","",'INPUT DATA'!L17) | T21: =IF(COUNT(K21:S21)=0,"",ROUND((K21+L21+M21+N21+O21+S21)/6,0)) | U21: =IF(T21="","",_xlfn.RANK.AVG(T21,$T$15:$T$115))
B22: 8 | C22: =IF('INPUT DATA'!L18="","",'INPUT DATA'!L18) | T22: =IF(COUNT(K22:S22)=0,"",ROUND((K22+L22+M22+N22+O22+S22)/6,0)) | U22: =IF(T22="","",_xlfn.RANK.AVG(T22,$T$15:$T$115))
B23: 9 | C23: =IF('INPUT DATA'!L19="","",'INPUT DATA'!L19) | T23: =IF(COUNT(K23:S23)=0,"",ROUND((K23+L23+M23+N23+O23+S23)/6,0)) | U23: =IF(T23="","",_xlfn.RANK.AVG(T23,$T$15:$T$115))
B24: 10 | C24: =IF('INPUT DATA'!L20="","",'INPUT DATA'!L20) | T24: =IF(COUNT(K24:S24)=0,"",ROUND((K24+L24+M24+N24+O24+S24)/6,0)) | U24: =IF(T24="","",_xlfn.RANK.AVG(T24,$T$15:$T$115))
B25: 11 | C25: =IF('INPUT DATA'!L21="","",'INPUT DATA'!L21) | T25: =IF(COUNT(K25:S25)=0,"",ROUND((K25+L25+M25+N25+O25+S25)/6,0)) | U25: =IF(T25="","",_xlfn.RANK.AVG(T25,$T$15:$T$115))
B26: 12 | C26: =IF('INPUT DATA'!L22="","",'INPUT DATA'!L22) | T26: =IF(COUNT(K26:S26)=0,"",ROUND((K26+L26+M26+N26+O26+S26)/6,0)) | U26: =IF(T26="","",_xlfn.RANK.AVG(T26,$T$15:$T$115))
B27: 13 | C27: =IF('INPUT DATA'!L23="","",'INPUT DATA'!L23) | T27: =IF(COUNT(K27:S27)=0,"",ROUND((K27+L27+M27+N27+O27+S27)/6,0)) | U27: =IF(T27="","",_xlfn.RANK.AVG(T27,$T$15:$T$115))
B28: 14 | C28: =IF('INPUT DATA'!L24="","",'INPUT DATA'!L24) | T28: =IF(COUNT(K28:S28)=0,"",ROUND((K28+L28+M28+N28+O28+S28)/6,0)) | U28: =IF(T28="","",_xlfn.RANK.AVG(T28,$T$15:$T$115))
B29: 15 | C29: =IF('INPUT DATA'!L25="","",'INPUT DATA'!L25) | T29: =IF(COUNT(K29:S29)=0,"",ROUND((K29+L29+M29+N29+O29+S29)/6,0)) | U29: =IF(T29="","",_xlfn.RANK.AVG(T29,$T$15:$T$115))
... B64: 50 | C64: =IF('INPUT DATA'!L60="","",'INPUT DATA'!L60) | T64: =IF(COUNT(K64:S64)=0,"",ROUND((K64+L64+M64+N64+O64+S64)/6,0)) | U64: =IF(T64="","",_xlfn.RANK.AVG(T64,$T$15:$T$115))
B65: FEMALE
B66: 1 | C66: =IF('INPUT DATA'!Q11="","",'INPUT DATA'!Q11) | F66: =IF('INPUT DATA'!T11="","",'INPUT DATA'!T11) | H66: =IF('INPUT DATA'!S11="","",'INPUT DATA'!S11) | I66: =IF(H66="","",DATEDIF(H66,TODAY(),"Y")) | J66: F | T66: =IF(COUNT(K66:S66)=0,"",ROUND((K66+L66+M66+N66+O66+S66)/6,0)) | U66: =IF(T66="","",_xlfn.RANK.AVG(T66,$T$15:$T$115))
B67: 2 | C67: =IF('INPUT DATA'!Q12="","",'INPUT DATA'!Q12) | F67: =IF('INPUT DATA'!T12="","",'INPUT DATA'!T12) | H67: =IF('INPUT DATA'!S12="","",'INPUT DATA'!S12) | J67: F | T67: =IF(COUNT(K67:S67)=0,"",ROUND((K67+L67+M67+N67+O67+S67)/6,0)) | U67: =IF(T67="","",_xlfn.RANK.AVG(T67,$T$15:$T$115))
B68: 3 | C68: =IF('INPUT DATA'!Q13="","",'INPUT DATA'!Q13) | F68: =IF('INPUT DATA'!T13="","",'INPUT DATA'!T13) | H68: =IF('INPUT DATA'!S13="","",'INPUT DATA'!S13) | J68: F | T68: =IF(COUNT(K68:S68)=0,"",ROUND((K68+L68+M68+N68+O68+S68)/6,0)) | U68: =IF(T68="","",_xlfn.RANK.AVG(T68,$T$15:$T$115))
B69: 4 | C69: =IF('INPUT DATA'!Q14="","",'INPUT DATA'!Q14) | F69: =IF('INPUT DATA'!T14="","",'INPUT DATA'!T14) | H69: =IF('INPUT DATA'!S14="","",'INPUT DATA'!S14) | T69: =IF(COUNT(K69:S69)=0,"",ROUND((K69+L69+M69+N69+O69+S69)/6,0)) | U69: =IF(T69="","",_xlfn.RANK.AVG(T69,$T$15:$T$115))
B70: 5 | C70: =IF('INPUT DATA'!Q15="","",'INPUT DATA'!Q15) | F70: =IF('INPUT DATA'!T15="","",'INPUT DATA'!T15) | H70: =IF('INPUT DATA'!S15="","",'INPUT DATA'!S15) | T70: =IF(COUNT(K70:S70)=0,"",ROUND((K70+L70+M70+N70+O70+S70)/6,0)) | U70: =IF(T70="","",_xlfn.RANK.AVG(T70,$T$15:$T$115))
B71: 6 | C71: =IF('INPUT DATA'!Q16="","",'INPUT DATA'!Q16) | F71: =IF('INPUT DATA'!T16="","",'INPUT DATA'!T16) | H71: =IF('INPUT DATA'!S16="","",'INPUT DATA'!S16) | T71: =IF(COUNT(K71:S71)=0,"",ROUND((K71+L71+M71+N71+O71+S71)/6,0)) | U71: =IF(T71="","",_xlfn.RANK.AVG(T71,$T$15:$T$115))
B72: 7 | C72: =IF('INPUT DATA'!Q17="","",'INPUT DATA'!Q17) | F72: =IF('INPUT DATA'!T17="","",'INPUT DATA'!T17) | H72: =IF('INPUT DATA'!S17="","",'INPUT DATA'!S17) | T72: =IF(COUNT(K72:S72)=0,"",ROUND((K72+L72+M72+N72+O72+S72)/6,0)) | U72: =IF(T72="","",_xlfn.RANK.AVG(T72,$T$15:$T$115))
B73: 8 | C73: =IF('INPUT DATA'!Q18="","",'INPUT DATA'!Q18) | F73: =IF('INPUT DATA'!T18="","",'INPUT DATA'!T18) | H73: =IF('INPUT DATA'!S18="","",'INPUT DATA'!S18) | T73: =IF(COUNT(K73:S73)=0,"",ROUND((K73+L73+M73+N73+O73+S73)/6,0)) | U73: =IF(T73="","",_xlfn.RANK.AVG(T73,$T$15:$T$115))
B74: 9 | C74: =IF('INPUT DATA'!Q19="","",'INPUT DATA'!Q19) | F74: =IF('INPUT DATA'!T19="","",'INPUT DATA'!T19) | H74: =IF('INPUT DATA'!S19="","",'INPUT DATA'!S19) | T74: =IF(COUNT(K74:S74)=0,"",ROUND((K74+L74+M74+N74+O74+S74)/6,0)) | U74: =IF(T74="","",_xlfn.RANK.AVG(T74,$T$15:$T$115))
B75: 10 | C75: =IF('INPUT DATA'!Q20="","",'INPUT DATA'!Q20) | F75: =IF('INPUT DATA'!T20="","",'INPUT DATA'!T20) | H75: =IF('INPUT DATA'!S20="","",'INPUT DATA'!S20) | T75: =IF(COUNT(K75:S75)=0,"",ROUND((K75+L75+M75+N75+O75+S75)/6,0)) | U75: =IF(T75="","",_xlfn.RANK.AVG(T75,$T$15:$T$115))
B76: 11 | C76: =IF('INPUT DATA'!Q21="","",'INPUT DATA'!Q21) | F76: =IF('INPUT DATA'!T21="","",'INPUT DATA'!T21) | H76: =IF('INPUT DATA'!S21="","",'INPUT DATA'!S21) | T76: =IF(COUNT(K76:S76)=0,"",ROUND((K76+L76+M76+N76+O76+S76)/6,0)) | U76: =IF(T76="","",_xlfn.RANK.AVG(T76,$T$15:$T$115))
B77: 12 | C77: =IF('INPUT DATA'!Q22="","",'INPUT DATA'!Q22) | F77: =IF('INPUT DATA'!T22="","",'INPUT DATA'!T22) | H77: =IF('INPUT DATA'!S22="","",'INPUT DATA'!S22) | T77: =IF(COUNT(K77:S77)=0,"",ROUND((K77+L77+M77+N77+O77+S77)/6,0)) | U77: =IF(T77="","",_xlfn.RANK.AVG(T77,$T$15:$T$115))
B78: 13 | C78: =IF('INPUT DATA'!Q23="","",'INPUT DATA'!Q23) | F78: =IF('INPUT DATA'!T23="","",'INPUT DATA'!T23) | H78: =IF('INPUT DATA'!S23="","",'INPUT DATA'!S23) | T78: =IF(COUNT(K78:S78)=0,"",ROUND((K78+L78+M78+N78+O78+S78)/6,0)) | U78: =IF(T78="","",_xlfn.RANK.AVG(T78,$T$15:$T$115))
B79: 14 | C79: =IF('INPUT DATA'!Q24="","",'INPUT DATA'!Q24) | F79: =IF('INPUT DATA'!T24="","",'INPUT DATA'!T24) | H79: =IF('INPUT DATA'!S24="","",'INPUT DATA'!S24) | T79: =IF(COUNT(K79:S79)=0,"",ROUND((K79+L79+M79+N79+O79+S79)/6,0)) | U79: =IF(T79="","",_xlfn.RANK.AVG(T79,$T$15:$T$115))
B80: 15 | C80: =IF('INPUT DATA'!Q25="","",'INPUT DATA'!Q25) | F80: =IF('INPUT DATA'!T25="","",'INPUT DATA'!T25) | H80: =IF('INPUT DATA'!S25="","",'INPUT DATA'!S25) | T80: =IF(COUNT(K80:S80)=0,"",ROUND((K80+L80+M80+N80+O80+S80)/6,0)) | U80: =IF(T80="","",_xlfn.RANK.AVG(T80,$T$15:$T$115))
...

Sheet ATTENDANCE RECORD SUMMARY
A1: ATTENDANCE RECORD
D5: REGION | E5: ='INPUT DATA'!F10 -> NCR | H5: DIVISION | I5: ='INPUT DATA'!F11 -> LAS PINAS
D7: SCHOOL NAME | E7: ='INPUT DATA'!F16 -> LAS PINAS EAST NATIONAL HIGH SCHOOL | H7: SCHOOL ID | I7: ='INPUT DATA'!F15 -> 305434 | L7: SCHOOL YEAR | N7: ='INPUT DATA'!F18 -> 2026-2027
B10: LEARNERS' NAMES | F10: GRADE LEVEL | G10: ='INPUT DATA'!F27 -> 10 | K10: ADVISER | L10: ='INPUT DATA'!F26 -> ROSALINDA S. VALE
F11: SECTION | G11: ='INPUT DATA'!F28 -> PAMAYPAY
F12: JUN | G12: JUL | H12: AUG | I12: SEP | J12: OCT | K12: NOV | L12: DEC | M12: JAN | N12: FEB | O12: MAR | P12: APRIL
B13: MALE
B14: 1 | C14: =IF('INPUT DATA'!L11="","",'INPUT DATA'!L11) -> A
B15: 2 | C15: =IF('INPUT DATA'!L12="","",'INPUT DATA'!L12) -> B
B16: 3 | C16: =IF('INPUT DATA'!L13="","",'INPUT DATA'!L13)
B17: 4 | C17: =IF('INPUT DATA'!L14="","",'INPUT DATA'!L14)
B18: 5 | C18: =IF('INPUT DATA'!L15="","",'INPUT DATA'!L15)
B19: 6 | C19: =IF('INPUT DATA'!L16="","",'INPUT DATA'!L16)
B20: 7 | C20: =IF('INPUT DATA'!L17="","",'INPUT DATA'!L17)
B21: 8 | C21: =IF('INPUT DATA'!L18="","",'INPUT DATA'!L18)
B22: 9 | C22: =IF('INPUT DATA'!L19="","",'INPUT DATA'!L19)
B23: 10 | C23: =IF('INPUT DATA'!L20="","",'INPUT DATA'!L20)
B24: 11 | C24: =IF('INPUT DATA'!L21="","",'INPUT DATA'!L21)
B25: 12 | C25: =IF('INPUT DATA'!L22="","",'INPUT DATA'!L22)
... B63: 50 | C63: =IF('INPUT DATA'!L60="","",'INPUT DATA'!L60)
B64: FEMALE
B65: 1 | C65: =IF('INPUT DATA'!Q11="","",'INPUT DATA'!Q11) | F65: 15 | G65: 20 | H65: 20 | I65: 20 | J65: 17 | K65: 20 | L65: 20 | M65: 18 | N65: 18 | O65: 20 | P65: 2
B66: 2 | C66: =IF('INPUT DATA'!Q12="","",'INPUT DATA'!Q12) | F66: 20 | G66: 16 | H66: 20 | I66: 19 | J66: 20 | K66: 20 | L66: 20 | M66: 18 | N66: 18 | O66: 20 | P66: 5
B67: 3 | C67: =IF('INPUT DATA'!Q13="","",'INPUT DATA'!Q13) | F67: 18 | G67: 20 | H67: 20 | I67: 20 | J67: 20 | K67: 19 | L67: 20 | M67: 18 | N67: 18 | O67: 20 | P67: 3
B68: 4 | C68: =IF('INPUT DATA'!Q14="","",'INPUT DATA'!Q14)
B69: 5 | C69: =IF('INPUT DATA'!Q15="","",'INPUT DATA'!Q15)
B70: 6 | C70: =IF('INPUT DATA'!Q16="","",'INPUT DATA'!Q16)
B71: 7 | C71: =IF('INPUT DATA'!Q17="","",'INPUT DATA'!Q17)
B72: 8 | C72: =IF('INPUT DATA'!Q18="","",'INPUT DATA'!Q18)
B73: 9 | C73: =IF('INPUT DATA'!Q19="","",'INPUT DATA'!Q19)
B74: 10 | C74: =IF('INPUT DATA'!Q20="","",'INPUT DATA'!Q20)
B75: 11 | C75: =IF('INPUT DATA'!Q21="","",'INPUT DATA'!Q21)
B76: 12 | C76: =IF('INPUT DATA'!Q22="","",'INPUT DATA'!Q22)
B77: 13 | C77: =IF('INPUT DATA'!Q23="","",'INPUT DATA'!Q23)
B78: 14 | C78: =IF('INPUT DATA'!Q24="","",'INPUT DATA'!Q24)
B79: 15 | C79: =IF('INPUT DATA'!Q25="","",'INPUT DATA'!Q25)
... B114: 50 | C114: =IF('INPUT DATA'!Q60="","",'INPUT DATA'!Q60)
B116: TOTAL NUMBER OF SCHOOL DAYS | E116: TOTAL | F116: JUN | G116: JUL | H116: AUG | I116: SEP | J116: OCT | K116: NOV | L116: DEC | M116: JAN | N116: FEB | O116: MAR | P116: APR
E117: =SUM(F117:P117) -> 201 | F117: 16 | G117: 23 | H117: 19 | I117: 22 | J117: 22 | K117: 19 | L117: 13 | M117: 20 | N117: 20 | O117: 21 | P117: 6

Sheet FINAL GRADES
A1: FINAL GRADES
C6: REGION | E6: ='INPUT DATA'!F10 -> NCR | J6: DIVISION | L6: ='INPUT DATA'!F11 -> LAS PINAS
C7: SCHOOL NAME | E7: ='INPUT DATA'!F16 -> LAS PINAS EAST NATIONAL HIGH SCHOOL | J7: SCHOOL ID | L7: ='INPUT DATA'!F15 -> 305434 | P7: SCHOOL YEAR | R7: ='INPUT DATA'!F18 -> 2026-2027
B10: LEARNERS' NAMES | F10: GRADE LEVEL | H10: ='INPUT DATA'!F27 -> 10 | N10: ADVISER | P10: EUNICE FERNANDEZ
F11: SECTION | H11: ='INPUT DATA'!F28 -> PAMAYPAY
F12: FIRST TERM | J12: SECOND TERM | M12: THIRD TERM | P12: AVERAGE | S12: RANK
B14: MALE
B15: 1 | C15: =IF('INPUT DATA'!L11="","",'INPUT DATA'!L11) -> A | F15: {=IF(TRIM(C15)="","",IFERROR(_xlfn.XLOOKUP(TRIM(C15),'TERM 1 SUMMARY'!$C$15:$C$115,'TERM 1 SUMMARY'!$T$15:$T$115),""))} | J15: {=IF(TRIM(C15)="","",IFERROR(_xlfn.XLOOKUP(TRIM(C15),'TERM 2 SUMMARY A'!$C$15:$C$115,'TERM 2 SUMMARY A'!$T$15:T$115),""))} | M15: {=IF(TRIM(C15)="","",IFERROR(_xlfn.XLOOKUP(TRIM(C15),'TERM 3 SUMMARY B'!$C$15:$C$115,'TERM 3 SUMMARY B'!$T$15:$T$115),""))} | P15: =IF(C15="","",IF(COUNT($F15:$M15)=0,"",SUM($F15:$M15)/3)) | S15: =IF(P15="","",_xlfn.RANK.AVG(P15,$P$15:$P$115))
B16: 2 | C16: =IF('INPUT DATA'!L12="","",'INPUT DATA'!L12) -> B | F16: {=IF(TRIM(C16)="","",IFERROR(_xlfn.XLOOKUP(TRIM(C16),'TERM 1 SUMMARY'!$C$15:$C$115,'TERM 1 SUMMARY'!$T$15:$T$115),""))} | J16: {=IF(TRIM(C16)="","",IFERROR(_xlfn.XLOOKUP(TRIM(C16),'TERM 2 SUMMARY A'!$C$15:$C$115,'TERM 2 SUMMARY A'!$T$15:T$115),""))} | M16: {=IF(TRIM(C16)="","",IFERROR(_xlfn.XLOOKUP(TRIM(C16),'TERM 3 SUMMARY B'!$C$15:$C$115,'TERM 3 SUMMARY B'!$T$15:$T$115),""))} | P16: =IF(C16="","",IF(COUNT($F16:$M16)=0,"",SUM($F16:$M16)/3)) | S16: =IF(P16="","",_xlfn.RANK.AVG(P16,$P$15:$P$115))
